<?xml version="1.0" encoding="utf-8"?>

<!-- 05062025-alpha-1 -->

<robot
  name="fourier_left_hand_12dof">
  <link
    name="L_hand_base_link">
    <inertial>
      <origin
        xyz="-0.0025784 -0.0012134 -0.054617"
        rpy="0 0 0" />
      <mass
        value="0.26434" />
      <inertia
        ixx="0.0002497"
        ixy="7.84E-06"
        ixz="9.3E-07"
        iyy="0.00034878"
        iyz="8E-07"
        izz="0.00018825" />
    </inertial>
    <visual>
      <origin
        xyz="0 0 0"
        rpy="0 0 0" />
      <geometry>
        <mesh
          filename="../meshes/fourier_hand_12dof_v2/L_hand_base_link.STL" />
      </geometry>
      <material
        name="">
        <color
          rgba="1 1 1 1" />
      </material>
    </visual>
    <collision>
      <origin
        xyz="0 0 0"
        rpy="0 0 0" />
      <geometry>
        <mesh
          filename="../meshes/fourier_hand_12dof_v2/L_hand_base_link.STL" />
      </geometry>
    </collision>
  </link>
  <link
    name="L_hand_wrist_link">
  </link>
  <joint
    name="L_hand_wrist_joint"
    type="fixed">
    <origin
      xyz="0 0 0"
      rpy="0 0 0" />
    <parent
      link="L_hand_base_link" />
    <child
      link="L_hand_wrist_link" />
    <axis
      xyz="0 0 0" />
  </joint>


  <link
    name="L_thumb_proximal_yaw_link">
    <inertial>
      <origin
        xyz="0.01106 -0.00242 -0.001058"
        rpy="0 0 0" />
      <mass
        value="0.034977" />
      <inertia
        ixx="2.26E-06"
        ixy="7.6E-07"
        ixz="-3.3E-07"
        iyy="5E-06"
        iyz="5E-08"
        izz="4.66E-06" />
    </inertial>
    <visual>
      <origin
        xyz="0 0 0"
        rpy="0 0 0" />
      <geometry>
        <mesh
          filename="../meshes/fourier_hand_12dof_v2/L_thumb_proximal_yaw_link.STL" />
      </geometry>
      <material
        name="">
        <color
          rgba="1 1 1 1" />
      </material>
    </visual>
    <collision>
      <origin
        xyz="0 0 0"
        rpy="0 0 0" />
      <geometry>
        <mesh
          filename="../meshes/fourier_hand_12dof_v2/L_thumb_proximal_yaw_link.STL" />
      </geometry>
    </collision>
  </link>
  <joint
    name="L_thumb_proximal_yaw_joint"
    type="revolute">
    <origin
      xyz="0.014 -0.012 -0.022446"
      rpy="0 0 0" />
    <parent
      link="L_hand_base_link" />
    <child
      link="L_thumb_proximal_yaw_link" />
    <axis
      xyz="0 0 1" />
    <limit
      lower="-1.3579"
      upper="0"
      effort="0"
      velocity="0" />
  </joint>
  <link
    name="L_thumb_proximal_pitch_link">
    <inertial>
      <origin
        xyz="0.021577 -0.003516 -2.151E-05"
        rpy="0 0 0" />
      <mass
        value="0.047552" />
      <inertia
        ixx="4.41E-06"
        ixy="-1.9E-07"
        ixz="-3E-08"
        iyy="1.192E-05"
        iyz="0"
        izz="1.307E-05" />
    </inertial>
    <visual>
      <origin
        xyz="0 0 0"
        rpy="0 0 0" />
      <geometry>
        <mesh
          filename="../meshes/fourier_hand_12dof_v2/L_thumb_proximal_pitch_link.STL" />
      </geometry>
      <material
        name="">
        <color
          rgba="1 1 1 1" />
      </material>
    </visual>
    <collision>
      <origin
        xyz="0 0 0"
        rpy="0 0 0" />
      <geometry>
        <mesh
          filename="../meshes/fourier_hand_12dof_v2/L_thumb_proximal_pitch_link.STL" />
      </geometry>
    </collision>
  </link>
  <joint
    name="L_thumb_proximal_pitch_joint"
    type="revolute">
    <origin
      xyz="0.03385 -0.0078588 -0.0005"
      rpy="-1.5708 0.037538 -0.22813" />
    <parent
      link="L_thumb_proximal_yaw_link" />
    <child
      link="L_thumb_proximal_pitch_link" />
    <axis
      xyz="0 0 1" />
    <limit
      lower="0"
      upper="1.206"
      effort="0"
      velocity="0" />
  </joint>
  <link
    name="L_thumb_distal_link">
    <inertial>
      <origin
        xyz="0.016377 -0.0025204 0"
        rpy="0 0 0" />
      <mass
        value="0.021803" />
      <inertia
        ixx="1.42E-06"
        ixy="-4.3E-07"
        ixz="0"
        iyy="3.85E-06"
        iyz="0"
        izz="3.8E-06" />
    </inertial>
    <visual>
      <origin
        xyz="0 0 0"
        rpy="0 0 0" />
      <geometry>
        <mesh
          filename="../meshes/fourier_hand_12dof_v2/L_thumb_distal_link.STL" />
      </geometry>
      <material
        name="">
        <color
          rgba="1 1 1 1" />
      </material>
    </visual>
    <collision>
      <origin
        xyz="0 0 0"
        rpy="0 0 0" />
      <geometry>
        <mesh
          filename="../meshes/fourier_hand_12dof_v2/L_thumb_distal_link.STL" />
      </geometry>
    </collision>
  </link>
  <joint
    name="L_thumb_distal_joint"
    type="revolute">
    <origin
      xyz="0.051711 0.0054792 0"
      rpy="0 0 -0.12355" />
    <parent
      link="L_thumb_proximal_pitch_link" />
    <child
      link="L_thumb_distal_link" />
    <axis
      xyz="0 0 1" />
    <limit
      lower="0"
      upper="1.2078"
      effort="0"
      velocity="0" />
  </joint>

  <link name="L_thumb_tip_link">
    <visual>
      <origin
        xyz="0 0 0"
        rpy="0 0 0" />
      <geometry>
        <sphere radius="0.005" />
      </geometry>
      <material name="yellow">
        <color rgba="0.9 1 0 1" />
      </material>
    </visual>
  </link>
  <joint name="L_thumb_tip_joint" type="fixed">
    <parent link="L_thumb_distal_link" />
    <child link="L_thumb_tip_link" />
    <origin rpy="0 0 0" xyz="0.035 0.001 0" />
  </joint>


  <link
    name="L_index_metacarpal_link">
    <inertial>
      <origin
        xyz="-0.012286 -0.01381 -3.526E-05"
        rpy="0 0 0" />
      <mass
        value="0.028947" />
      <inertia
        ixx="1.91E-06"
        ixy="-8.7E-07"
        ixz="-3E-08"
        iyy="3.56E-06"
        iyz="-1E-08"
        izz="4.8E-06" />
    </inertial>
    <visual>
      <origin
        xyz="0 0 0"
        rpy="0 0 0" />
      <geometry>
        <mesh
          filename="../meshes/fourier_hand_12dof_v2/L_index_metacarpal_link.STL" />
      </geometry>
      <material
        name="">
        <color
          rgba="1 1 1 1" />
      </material>
    </visual>
    <collision>
      <origin
        xyz="0 0 0"
        rpy="0 0 0" />
      <geometry>
        <mesh
          filename="../meshes/fourier_hand_12dof_v2/L_index_metacarpal_link.STL" />
      </geometry>
    </collision>
  </link>
  <joint
    name="L_index_metacarpal_joint"
    type="revolute">
    <origin
      xyz="0.0305 -0.0113 -0.088496"
      rpy="0 1.5295 -3.1416" />
    <parent
      link="L_hand_base_link" />
    <child
      link="L_index_metacarpal_link" />
    <axis
      xyz="0 1 0" />
    <limit
      lower="0"
      upper="0.295"
      effort="0"
      velocity="0" />
  </joint>
  <link
    name="L_index_proximal_link">
    <inertial>
      <origin
        xyz="0.017015 0.0046443 2.868E-05"
        rpy="0 0 0" />
      <mass
        value="0.035619" />
      <inertia
        ixx="2.19E-06"
        ixy="-3E-08"
        ixz="3E-08"
        iyy="5.3E-06"
        iyz="0"
        izz="5.7E-06" />
    </inertial>
    <visual>
      <origin
        xyz="0 0 0"
        rpy="0 0 0" />
      <geometry>
        <mesh
          filename="../meshes/fourier_hand_12dof_v2/L_index_proximal_link.STL" />
      </geometry>
      <material
        name="">
        <color
          rgba="1 1 1 1" />
      </material>
    </visual>
    <collision>
      <origin
        xyz="0 0 0"
        rpy="0 0 0" />
      <geometry>
        <mesh
          filename="../meshes/fourier_hand_12dof_v2/L_index_proximal_link.STL" />
      </geometry>
    </collision>
  </link>
  <joint
    name="L_index_proximal_joint"
    type="revolute">
    <origin
      xyz="0.012 0 0"
      rpy="-3.1416 0 0.041438" />
    <parent
      link="L_index_metacarpal_link" />
    <child
      link="L_index_proximal_link" />
    <axis
      xyz="0 0 1" />
    <limit
      lower="-1.4172"
      upper="0"
      effort="0"
      velocity="0" />
  </joint>
  <link
    name="L_index_intermediate_link">
    <inertial>
      <origin
        xyz="0.022061 0.00025969 0"
        rpy="0 0 0" />
      <mass
        value="0.019358" />
      <inertia
        ixx="9.3E-07"
        ixy="3.4E-07"
        ixz="0"
        iyy="4.38E-06"
        iyz="0"
        izz="4.27E-06" />
    </inertial>
    <visual>
      <origin
        xyz="0 0 0"
        rpy="0 0 0" />
      <geometry>
        <mesh
          filename="../meshes/fourier_hand_12dof_v2/L_index_intermediate_link.STL" />
      </geometry>
      <material
        name="">
        <color
          rgba="1 1 1 1" />
      </material>
    </visual>
    <collision>
      <origin
        xyz="0 0 0"
        rpy="0 0 0" />
      <geometry>
        <mesh
          filename="../meshes/fourier_hand_12dof_v2/L_index_intermediate_link.STL" />
      </geometry>
    </collision>
  </link>
  <joint
    name="L_index_intermediate_joint"
    type="revolute">
    <origin
      xyz="0.038938 0.0021905 0"
      rpy="0 0 -0.040106" />
    <parent
      link="L_index_proximal_link" />
    <child
      link="L_index_intermediate_link" />
    <axis
      xyz="0 0 1" />
    <limit
      lower="-1.4835"
      upper="0"
      effort="0"
      velocity="0" />
  </joint>

  <link name="L_index_tip_link">
    <visual>
      <origin
        xyz="0 0 0"
        rpy="0 0 0" />
      <geometry>
        <sphere radius="0.005" />
      </geometry>
      <material name="yellow">
        <color rgba="0.9 1 0 1" />
      </material>
    </visual>
  </link>
  <joint name="L_index_tip_joint" type="fixed">
    <parent link="L_index_intermediate_link" />
    <child link="L_index_tip_link" />
    <origin rpy="0 0 0" xyz="0.047 -0.003 0" />
  </joint>


  <link
    name="L_middle_proximal_link">
    <inertial>
      <origin
        xyz="0.016963 0.004834 2.667E-05"
        rpy="0 0 0" />
      <mass
        value="0.035619" />
      <inertia
        ixx="2.19E-06"
        ixy="-7E-08"
        ixz="3E-08"
        iyy="5.29E-06"
        iyz="0"
        izz="5.7E-06" />
    </inertial>
    <visual>
      <origin
        xyz="0 0 0"
        rpy="0 0 0" />
      <geometry>
        <mesh
          filename="../meshes/fourier_hand_12dof_v2/L_middle_proximal_link.STL" />
      </geometry>
      <material
        name="">
        <color
          rgba="1 1 1 1" />
      </material>
    </visual>
    <collision>
      <origin
        xyz="0 0 0"
        rpy="0 0 0" />
      <geometry>
        <mesh
          filename="../meshes/fourier_hand_12dof_v2/L_middle_proximal_link.STL" />
      </geometry>
    </collision>
  </link>
  <joint
    name="L_middle_proximal_joint"
    type="revolute">
    <origin
      xyz="0.0091 -0.0113 -0.10005"
      rpy="-1.5685 1.5182 -1.5685" />
    <parent
      link="L_hand_base_link" />
    <child
      link="L_middle_proximal_link" />
    <axis
      xyz="0 0 1" />
    <limit
      lower="-1.4172"
      upper="0"
      effort="0"
      velocity="0" />
  </joint>
  <link
    name="L_middle_intermediate_link">
    <inertial>
      <origin
        xyz="0.025092 0.00019 -4.33E-06"
        rpy="0 0 0" />
      <mass
        value="0.022377" />
      <inertia
        ixx="1.09E-06"
        ixy="5E-07"
        ixz="0"
        iyy="6.44E-06"
        iyz="0"
        izz="6.32E-06" />
    </inertial>
    <visual>
      <origin
        xyz="0 0 0"
        rpy="0 0 0" />
      <geometry>
        <mesh
          filename="../meshes/fourier_hand_12dof_v2/L_middle_intermediate_link.STL" />
      </geometry>
      <material
        name="">
        <color
          rgba="1 1 1 1" />
      </material>
    </visual>
    <collision>
      <origin
        xyz="0 0 0"
        rpy="0 0 0" />
      <geometry>
        <mesh
          filename="../meshes/fourier_hand_12dof_v2/L_middle_intermediate_link.STL" />
      </geometry>
    </collision>
  </link>
  <joint
    name="L_middle_intermediate_joint"
    type="revolute">
    <origin
      xyz="0.038912 0.0026251 0"
      rpy="0 -7.4325E-05 -0.04236" />
    <parent
      link="L_middle_proximal_link" />
    <child
      link="L_middle_intermediate_link" />
    <axis
      xyz="0 0 1" />
    <limit
      lower="-1.4835"
      upper="0"
      effort="0"
      velocity="0" />
  </joint>

  <link name="L_middle_tip_link">
    <visual>
      <origin
        xyz="0 0 0"
        rpy="0 0 0" />
      <geometry>
        <sphere radius="0.005" />
      </geometry>
      <material name="yellow">
        <color rgba="0.9 1 0 1" />
      </material>
    </visual>
  </link>
  <joint name="L_middle_tip_joint" type="fixed">
    <parent link="L_middle_intermediate_link" />
    <child link="L_middle_tip_link" />
    <origin rpy="0 0 0" xyz="0.055 -0.003 0" />
  </joint>

  <link
    name="L_ring_proximal_link">
    <inertial>
      <origin
        xyz="0.017015 0.0046443 2.868E-05"
        rpy="0 0 0" />
      <mass
        value="0.035619" />
      <inertia
        ixx="2.19E-06"
        ixy="-3E-08"
        ixz="3E-08"
        iyy="5.3E-06"
        iyz="0"
        izz="5.7E-06" />
    </inertial>
    <visual>
      <origin
        xyz="0 0 0"
        rpy="0 0 0" />
      <geometry>
        <mesh
          filename="../meshes/fourier_hand_12dof_v2/L_ring_proximal_link.STL" />
      </geometry>
      <material
        name="">
        <color
          rgba="1 1 1 1" />
      </material>
    </visual>
    <collision>
      <origin
        xyz="0 0 0"
        rpy="0 0 0" />
      <geometry>
        <mesh
          filename="../meshes/fourier_hand_12dof_v2/L_ring_proximal_link.STL" />
      </geometry>
    </collision>
  </link>
  <joint
    name="L_ring_proximal_joint"
    type="revolute">
    <origin
      xyz="-0.011187 -0.0113 -0.10003"
      rpy="-2.4727 1.504 -2.4716" />
    <parent
      link="L_hand_base_link" />
    <child
      link="L_ring_proximal_link" />
    <axis
      xyz="0 0 1" />
    <limit
      lower="-1.4172"
      upper="0"
      effort="0"
      velocity="0" />
  </joint>
  <link
    name="L_ring_intermediate_link">
    <inertial>
      <origin
        xyz="0.022061 0.00025969 0"
        rpy="0 0 0" />
      <mass
        value="0.019358" />
      <inertia
        ixx="9.3E-07"
        ixy="3.4E-07"
        ixz="0"
        iyy="4.38E-06"
        iyz="0"
        izz="4.27E-06" />
    </inertial>
    <visual>
      <origin
        xyz="0 0 0"
        rpy="0 0 0" />
      <geometry>
        <mesh
          filename="../meshes/fourier_hand_12dof_v2/L_ring_intermediate_link.STL" />
      </geometry>
      <material
        name="">
        <color
          rgba="1 1 1 1" />
      </material>
    </visual>
    <collision>
      <origin
        xyz="0 0 0"
        rpy="0 0 0" />
      <geometry>
        <mesh
          filename="../meshes/fourier_hand_12dof_v2/L_ring_intermediate_link.STL" />
      </geometry>
    </collision>
  </link>
  <joint
    name="L_ring_intermediate_joint"
    type="revolute">
    <origin
      xyz="0.038938 0.0021905 0"
      rpy="0 0 -0.040106" />
    <parent
      link="L_ring_proximal_link" />
    <child
      link="L_ring_intermediate_link" />
    <axis
      xyz="0 0 1" />
    <limit
      lower="-1.4835"
      upper="0"
      effort="0"
      velocity="0" />
  </joint>

  <link name="L_ring_tip_link">
    <visual>
      <origin
        xyz="0 0 0"
        rpy="0 0 0" />
      <geometry>
        <sphere radius="0.005" />
      </geometry>
      <material name="green">
        <color rgba="0.9 1 0 1" />
      </material>
    </visual>
  </link>
  <joint name="L_ring_tip_joint" type="fixed">
    <parent link="L_ring_intermediate_link" />
    <child link="L_ring_tip_link" />
    <origin rpy="0 0 0" xyz="0.045 -0.003 0" />
  </joint>


  <link
    name="L_pinky_proximal_link">
    <inertial>
      <origin
        xyz="0.017073 0.0044289 2.868E-05"
        rpy="0 0 0" />
      <mass
        value="0.035619" />
      <inertia
        ixx="2.19E-06"
        ixy="0"
        ixz="3E-08"
        iyy="5.3E-06"
        iyz="-1E-08"
        izz="5.7E-06" />
    </inertial>
    <visual>
      <origin
        xyz="0 0 0"
        rpy="0 0 0" />
      <geometry>
        <mesh
          filename="../meshes/fourier_hand_12dof_v2/L_pinky_proximal_link.STL" />
      </geometry>
      <material
        name="">
        <color
          rgba="1 1 1 1" />
      </material>
    </visual>
    <collision>
      <origin
        xyz="0 0 0"
        rpy="0 0 0" />
      <geometry>
        <mesh
          filename="../meshes/fourier_hand_12dof_v2/L_pinky_proximal_link.STL" />
      </geometry>
    </collision>
  </link>
  <joint
    name="L_pinky_proximal_joint"
    type="revolute">
    <origin
      xyz="-0.031472 -0.0113 -0.099245"
      rpy="-2.8742 1.4622 -2.8727" />
    <parent
      link="L_hand_base_link" />
    <child
      link="L_pinky_proximal_link" />
    <axis
      xyz="0 0 1" />
    <limit
      lower="-1.4172"
      upper="0"
      effort="0"
      velocity="0" />
  </joint>
  <link
    name="L_pinky_intermediate_link">
    <inertial>
      <origin
        xyz="0.018249 0.00057564 0"
        rpy="0 0 0" />
      <mass
        value="0.01622" />
      <inertia
        ixx="7.6E-07"
        ixy="2.1E-07"
        ixz="0"
        iyy="2.64E-06"
        iyz="0"
        izz="2.57E-06" />
    </inertial>
    <visual>
      <origin
        xyz="0 0 0"
        rpy="0 0 0" />
      <geometry>
        <mesh
          filename="../meshes/fourier_hand_12dof_v2/L_pinky_intermediate_link.STL" />
      </geometry>
      <material
        name="">
        <color
          rgba="1 1 1 1" />
      </material>
    </visual>
    <collision>
      <origin
        xyz="0 0 0"
        rpy="0 0 0" />
      <geometry>
        <mesh
          filename="../meshes/fourier_hand_12dof_v2/L_pinky_intermediate_link.STL" />
      </geometry>
    </collision>
  </link>
  <joint
    name="L_pinky_intermediate_joint"
    type="revolute">
    <origin
      xyz="0.038963 0.0016981 0"
      rpy="0 0 -0.036802" />
    <parent
      link="L_pinky_proximal_link" />
    <child
      link="L_pinky_intermediate_link" />
    <axis
      xyz="0 0 1" />
    <limit
      lower="-1.4835"
      upper="0"
      effort="0"
      velocity="0" />
  </joint>

  <link name="L_pinky_tip_link">
    <visual>
      <origin
        xyz="0 0 0"
        rpy="0 0 0" />
      <geometry>
        <sphere radius="0.005" />
      </geometry>
      <material name="yellow">
        <color rgba="0.9 1 0 1" />
      </material>
    </visual>
  </link>
  <joint name="L_pinky_tip_joint" type="fixed">
    <parent link="L_pinky_intermediate_link" />
    <child link="L_pinky_tip_link" />
    <origin rpy="0 0 0" xyz="0.038 -0.003 0" />
  </joint>

</robot>
