<?xml version="1.0" encoding="utf-8"?>

<!-- 05062025-alpha-1 -->

<robot
  name="fourier_right_hand_12dof">
  <link
    name="R_hand_base_link">
    <inertial>
      <origin
        xyz="-0.0025758 0.0011993 -0.054629"
        rpy="0 0 0" />
      <mass
        value="0.26443" />
      <inertia
        ixx="0.00024968"
        ixy="-7.92E-06"
        ixz="7.5E-07"
        iyy="0.00034903"
        iyz="-8.4E-07"
        izz="0.00018834" />
    </inertial>
    <visual>
      <origin
        xyz="0 0 0"
        rpy="0 0 0" />
      <geometry>
        <mesh
          filename="../meshes/fourier_hand_12dof_v2/R_hand_base_link.STL" />
      </geometry>
      <material
        name="">
        <color
          rgba="1 1 1 1" />
      </material>
    </visual>
    <collision>
      <origin
        xyz="0 0 0"
        rpy="0 0 0" />
      <geometry>
        <mesh
          filename="../meshes/fourier_hand_12dof_v2/R_hand_base_link.STL" />
      </geometry>
    </collision>
  </link>

  <link
    name="R_hand_wrist_link">
  </link>
  <joint
    name="R_hand_wrist_joint"
    type="fixed">
    <origin
      xyz="0 0 0"
      rpy="0 0 0" />
    <parent
      link="R_hand_base_link" />
    <child
      link="R_hand_wrist_link" />
    <axis
      xyz="0 0 0" />
  </joint>


  <link
    name="R_thumb_proximal_yaw_link">
    <inertial>
      <origin
        xyz="0.011297 -0.0024139 0.00088027"
        rpy="0 0 0" />
      <mass
        value="0.03498" />
      <inertia
        ixx="2.28E-06"
        ixy="8E-07"
        ixz="3.1E-07"
        iyy="4.96E-06"
        iyz="-3E-08"
        izz="4.62E-06" />
    </inertial>
    <visual>
      <origin
        xyz="0 0 0"
        rpy="0 0 0" />
      <geometry>
        <mesh
          filename="../meshes/fourier_hand_12dof_v2/R_thumb_proximal_yaw_link.STL" />
      </geometry>
      <material
        name="">
        <color
          rgba="1 1 1 1" />
      </material>
    </visual>
    <collision>
      <origin
        xyz="0 0 0"
        rpy="0 0 0" />
      <geometry>
        <mesh
          filename="../meshes/fourier_hand_12dof_v2/R_thumb_proximal_yaw_link.STL" />
      </geometry>
    </collision>
  </link>
  <joint
    name="R_thumb_proximal_yaw_joint"
    type="revolute">
    <origin
      xyz="0.014 0.012 -0.022546"
      rpy="-3.1416 0 0" />
    <parent
      link="R_hand_base_link" />
    <child
      link="R_thumb_proximal_yaw_link" />
    <axis
      xyz="0 0 1" />
    <limit
      lower="-1.3579"
      upper="0"
      effort="0"
      velocity="0" />
  </joint>
  <link
    name="R_thumb_proximal_pitch_link">
    <inertial>
      <origin
        xyz="0.02157 -0.0035616 -2.386E-05"
        rpy="0 0 0" />
      <mass
        value="0.047583" />
      <inertia
        ixx="4.41E-06"
        ixy="-1.7E-07"
        ixz="-3E-08"
        iyy="1.194E-05"
        iyz="0"
        izz="1.308E-05" />
    </inertial>
    <visual>
      <origin
        xyz="0 0 0"
        rpy="0 0 0" />
      <geometry>
        <mesh
          filename="../meshes/fourier_hand_12dof_v2/R_thumb_proximal_pitch_link.STL" />
      </geometry>
      <material
        name="">
        <color
          rgba="1 1 1 1" />
      </material>
    </visual>
    <collision>
      <origin
        xyz="0 0 0"
        rpy="0 0 0" />
      <geometry>
        <mesh
          filename="../meshes/fourier_hand_12dof_v2/R_thumb_proximal_pitch_link.STL" />
      </geometry>
    </collision>
  </link>
  <joint
    name="R_thumb_proximal_pitch_joint"
    type="revolute">
    <origin
      xyz="0.03385 -0.0078588 0.0004"
      rpy="1.5708 -0.039876 -0.22822" />
    <parent
      link="R_thumb_proximal_yaw_link" />
    <child
      link="R_thumb_proximal_pitch_link" />
    <axis
      xyz="0 0 1" />
    <limit
      lower="0"
      upper="1.206"
      effort="0"
      velocity="0" />
  </joint>
  <link
    name="R_thumb_distal_link">
    <inertial>
      <origin
        xyz="0.016377 -0.0025204 0"
        rpy="0 0 0" />
      <mass
        value="0.021803" />
      <inertia
        ixx="1.42E-06"
        ixy="-4.3E-07"
        ixz="0"
        iyy="3.85E-06"
        iyz="0"
        izz="3.8E-06" />
    </inertial>
    <visual>
      <origin
        xyz="0 0 0"
        rpy="0 0 0" />
      <geometry>
        <mesh
          filename="../meshes/fourier_hand_12dof_v2/R_thumb_distal_link.STL" />
      </geometry>
      <material
        name="">
        <color
          rgba="1 1 1 1" />
      </material>
    </visual>
    <collision>
      <origin
        xyz="0 0 0"
        rpy="0 0 0" />
      <geometry>
        <mesh
          filename="../meshes/fourier_hand_12dof_v2/R_thumb_distal_link.STL" />
      </geometry>
    </collision>
  </link>
  <joint
    name="R_thumb_distal_joint"
    type="revolute">
    <origin
      xyz="0.051723 0.0053583 0"
      rpy="0 9.6078E-05 -0.12589" />
    <parent
      link="R_thumb_proximal_pitch_link" />
    <child
      link="R_thumb_distal_link" />
    <axis
      xyz="0 0 1" />
    <limit
      lower="0"
      upper="1.2078"
      effort="0"
      velocity="0" />
  </joint>

  <link name="R_thumb_tip_link">
    <visual>
      <origin
        xyz="0 0 0"
        rpy="0 0 0" />
      <geometry>
        <sphere radius="0.005" />
      </geometry>
      <material name="yellow">
        <color rgba="0.9 1 0 1" />
      </material>
    </visual>
  </link>
  <joint name="R_thumb_tip_joint" type="fixed">
    <parent link="R_thumb_distal_link" />
    <child link="R_thumb_tip_link" />
    <origin rpy="0 0 0" xyz="0.037 0.001 0" />
  </joint>


  <link
    name="R_index_metacarpal_link">
    <inertial>
      <origin
        xyz="-0.012286 0.01381 3.526E-05"
        rpy="0 0 0" />
      <mass
        value="0.028947" />
      <inertia
        ixx="1.91E-06"
        ixy="8.7E-07"
        ixz="3E-08"
        iyy="3.56E-06"
        iyz="-1E-08"
        izz="4.8E-06" />
    </inertial>
    <visual>
      <origin
        xyz="0 0 0"
        rpy="0 0 0" />
      <geometry>
        <mesh
          filename="../meshes/fourier_hand_12dof_v2/R_index_metacarpal_link.STL" />
      </geometry>
      <material
        name="">
        <color
          rgba="1 1 1 1" />
      </material>
    </visual>
    <collision>
      <origin
        xyz="0 0 0"
        rpy="0 0 0" />
      <geometry>
        <mesh
          filename="../meshes/fourier_hand_12dof_v2/R_index_metacarpal_link.STL" />
      </geometry>
    </collision>
  </link>
  <joint
    name="R_index_metacarpal_joint"
    type="revolute">
    <origin
      xyz="0.0305 0.0113 -0.088496"
      rpy="0 1.5295 3.1416" />
    <parent
      link="R_hand_base_link" />
    <child
      link="R_index_metacarpal_link" />
    <axis
      xyz="0 1 0" />
    <limit
      lower="0"
      upper="0.295"
      effort="0"
      velocity="0" />
  </joint>
  <link
    name="R_index_proximal_link">
    <inertial>
      <origin
        xyz="0.017246 0.0047094 2.979E-05"
        rpy="0 0 0" />
      <mass
        value="0.035619" />
      <inertia
        ixx="2.18E-06"
        ixy="-1E-08"
        ixz="3E-08"
        iyy="5.26E-06"
        iyz="-1E-08"
        izz="5.69E-06" />
    </inertial>
    <visual>
      <origin
        xyz="0 0 0"
        rpy="0 0 0" />
      <geometry>
        <mesh
          filename="../meshes/fourier_hand_12dof_v2/R_index_proximal_link.STL" />
      </geometry>
      <material
        name="">
        <color
          rgba="1 1 1 1" />
      </material>
    </visual>
    <collision>
      <origin
        xyz="0 0 0"
        rpy="0 0 0" />
      <geometry>
        <mesh
          filename="../meshes/fourier_hand_12dof_v2/R_index_proximal_link.STL" />
      </geometry>
    </collision>
  </link>
  <joint
    name="R_index_proximal_joint"
    type="revolute">
    <origin
      xyz="0.012 0 0"
      rpy="0 0 -0.041438" />
    <parent
      link="R_index_metacarpal_link" />
    <child
      link="R_index_proximal_link" />
    <axis
      xyz="0 0 1" />
    <limit
      lower="-1.4172"
      upper="0"
      effort="0"
      velocity="0" />
  </joint>
  <link
    name="R_index_intermediate_link">
    <inertial>
      <origin
        xyz="0.022061 0.00025969 0"
        rpy="0 0 0" />
      <mass
        value="0.019358" />
      <inertia
        ixx="9.3E-07"
        ixy="3.4E-07"
        ixz="0"
        iyy="4.38E-06"
        iyz="0"
        izz="4.27E-06" />
    </inertial>
    <visual>
      <origin
        xyz="0 0 0"
        rpy="0 0 0" />
      <geometry>
        <mesh
          filename="../meshes/fourier_hand_12dof_v2/R_index_intermediate_link.STL" />
      </geometry>
      <material
        name="">
        <color
          rgba="1 1 1 1" />
      </material>
    </visual>
    <collision>
      <origin
        xyz="0 0 0"
        rpy="0 0 0" />
      <geometry>
        <mesh
          filename="../meshes/fourier_hand_12dof_v2/R_index_intermediate_link.STL" />
      </geometry>
    </collision>
  </link>
  <joint
    name="R_index_intermediate_joint"
    type="revolute">
    <origin
      xyz="0.038938 0.0021905 0"
      rpy="0 0 -0.040106" />
    <parent
      link="R_index_proximal_link" />
    <child
      link="R_index_intermediate_link" />
    <axis
      xyz="0 0 1" />
    <limit
      lower="-1.4835"
      upper="0"
      effort="0"
      velocity="0" />
  </joint>


  <link name="R_index_tip_link">
    <visual>
      <origin
        xyz="0 0 0"
        rpy="0 0 0" />
      <geometry>
        <sphere radius="0.005" />
      </geometry>
      <material name="yellow">
        <color rgba="0.9 1 0 1" />
      </material>
    </visual>
  </link>
  <joint name="R_index_tip_joint" type="fixed">
    <parent link="R_index_intermediate_link" />
    <child link="R_index_tip_link" />
    <origin rpy="0 0 0" xyz="0.047 -0.003 0" />
  </joint>


  <link
    name="R_middle_proximal_link">
    <inertial>
      <origin
        xyz="0.016963 0.004834 2.667E-05"
        rpy="0 0 0" />
      <mass
        value="0.035619" />
      <inertia
        ixx="2.19E-06"
        ixy="-7E-08"
        ixz="3E-08"
        iyy="5.29E-06"
        iyz="0"
        izz="5.7E-06" />
    </inertial>
    <visual>
      <origin
        xyz="0 0 0"
        rpy="0 0 0" />
      <geometry>
        <mesh
          filename="../meshes/fourier_hand_12dof_v2/R_middle_proximal_link.STL" />
      </geometry>
      <material
        name="">
        <color
          rgba="1 1 1 1" />
      </material>
    </visual>
    <collision>
      <origin
        xyz="0 0 0"
        rpy="0 0 0" />
      <geometry>
        <mesh
          filename="../meshes/fourier_hand_12dof_v2/R_middle_proximal_link.STL" />
      </geometry>
    </collision>
  </link>
  <joint
    name="R_middle_proximal_joint"
    type="revolute">
    <origin
      xyz="0.0091 0.0113 -0.10005"
      rpy="-1.5685 1.5182 1.573" />
    <parent
      link="R_hand_base_link" />
    <child
      link="R_middle_proximal_link" />
    <axis
      xyz="0 0 1" />
    <limit
      lower="-1.4172"
      upper="0"
      effort="0"
      velocity="0" />
  </joint>
  <link
    name="R_middle_intermediate_link">
    <inertial>
      <origin
        xyz="0.025092 0.00019001 -3.94E-06"
        rpy="0 0 0" />
      <mass
        value="0.022377" />
      <inertia
        ixx="1.09E-06"
        ixy="5E-07"
        ixz="0"
        iyy="6.44E-06"
        iyz="0"
        izz="6.32E-06" />
    </inertial>
    <visual>
      <origin
        xyz="0 0 0"
        rpy="0 0 0" />
      <geometry>
        <mesh
          filename="../meshes/fourier_hand_12dof_v2/R_middle_intermediate_link.STL" />
      </geometry>
      <material
        name="">
        <color
          rgba="1 1 1 1" />
      </material>
    </visual>
    <collision>
      <origin
        xyz="0 0 0"
        rpy="0 0 0" />
      <geometry>
        <mesh
          filename="../meshes/fourier_hand_12dof_v2/R_middle_intermediate_link.STL" />
      </geometry>
    </collision>
  </link>
  <joint
    name="R_middle_intermediate_joint"
    type="revolute">
    <origin
      xyz="0.038912 0.0026251 0"
      rpy="-0.0020273 -7.4325E-05 -0.04236" />
    <parent
      link="R_middle_proximal_link" />
    <child
      link="R_middle_intermediate_link" />
    <axis
      xyz="0 0 1" />
    <limit
      lower="-1.4835"
      upper="0"
      effort="0"
      velocity="0" />
  </joint>

  <link name="R_middle_tip_link">
    <visual>
      <origin
        xyz="0 0 0"
        rpy="0 0 0" />
      <geometry>
        <sphere radius="0.005" />
      </geometry>
      <material name="yellow">
        <color rgba="0.9 1 0 1" />
      </material>
    </visual>
  </link>
  <joint name="R_middle_tip_joint" type="fixed">
    <parent link="R_middle_intermediate_link" />
    <child link="R_middle_tip_link" />
    <origin rpy="0 0 0" xyz="0.055 -0.003 0" />
  </joint>


  <link
    name="R_ring_proximal_link">
    <inertial>
      <origin
        xyz="0.017015 0.0046443 2.868E-05"
        rpy="0 0 0" />
      <mass
        value="0.035619" />
      <inertia
        ixx="2.19E-06"
        ixy="-3E-08"
        ixz="3E-08"
        iyy="5.3E-06"
        iyz="0"
        izz="5.7E-06" />
    </inertial>
    <visual>
      <origin
        xyz="0 0 0"
        rpy="0 0 0" />
      <geometry>
        <mesh
          filename="../meshes/fourier_hand_12dof_v2/R_ring_proximal_link.STL" />
      </geometry>
      <material
        name="">
        <color
          rgba="1 1 1 1" />
      </material>
    </visual>
    <collision>
      <origin
        xyz="0 0 0"
        rpy="0 0 0" />
      <geometry>
        <mesh
          filename="../meshes/fourier_hand_12dof_v2/R_ring_proximal_link.STL" />
      </geometry>
    </collision>
  </link>
  <joint
    name="R_ring_proximal_joint"
    type="revolute">
    <origin
      xyz="-0.011187 0.0113 -0.10003"
      rpy="-0.6689 1.504 2.4716" />
    <parent
      link="R_hand_base_link" />
    <child
      link="R_ring_proximal_link" />
    <axis
      xyz="0 0 1" />
    <limit
      lower="-1.4172"
      upper="0"
      effort="0"
      velocity="0" />
  </joint>
  <link
    name="R_ring_intermediate_link">
    <inertial>
      <origin
        xyz="0.022061 0.00025969 0"
        rpy="0 0 0" />
      <mass
        value="0.019358" />
      <inertia
        ixx="9.3E-07"
        ixy="3.4E-07"
        ixz="0"
        iyy="4.38E-06"
        iyz="0"
        izz="4.27E-06" />
    </inertial>
    <visual>
      <origin
        xyz="0 0 0"
        rpy="0 0 0" />
      <geometry>
        <mesh
          filename="../meshes/fourier_hand_12dof_v2/R_ring_intermediate_link.STL" />
      </geometry>
      <material
        name="">
        <color
          rgba="1 1 1 1" />
      </material>
    </visual>
    <collision>
      <origin
        xyz="0 0 0"
        rpy="0 0 0" />
      <geometry>
        <mesh
          filename="../meshes/fourier_hand_12dof_v2/R_ring_intermediate_link.STL" />
      </geometry>
    </collision>
  </link>
  <joint
    name="R_ring_intermediate_joint"
    type="revolute">
    <origin
      xyz="0.038938 0.0021905 0"
      rpy="0 0 -0.040106" />
    <parent
      link="R_ring_proximal_link" />
    <child
      link="R_ring_intermediate_link" />
    <axis
      xyz="0 0 1" />
    <limit
      lower="-1.4835"
      upper="0"
      effort="0"
      velocity="0" />
  </joint>

  <link name="R_ring_tip_link">
    <visual>
      <origin
        xyz="0 0 0"
        rpy="0 0 0" />
      <geometry>
        <sphere radius="0.005" />
      </geometry>
      <material name="green">
        <color rgba="0.9 1 0 1" />
      </material>
    </visual>
  </link>
  <joint name="R_ring_tip_joint" type="fixed">
    <parent link="R_ring_intermediate_link" />
    <child link="R_ring_tip_link" />
    <origin rpy="0 0 0" xyz="0.045 -0.003 0" />
  </joint>


  <link
    name="R_pinky_proximal_link">
    <inertial>
      <origin
        xyz="0.017073 0.0044289 2.868E-05"
        rpy="0 0 0" />
      <mass
        value="0.035619" />
      <inertia
        ixx="2.19E-06"
        ixy="0"
        ixz="3E-08"
        iyy="5.3E-06"
        iyz="-1E-08"
        izz="5.7E-06" />
    </inertial>
    <visual>
      <origin
        xyz="0 0 0"
        rpy="0 0 0" />
      <geometry>
        <mesh
          filename="../meshes/fourier_hand_12dof_v2/R_pinky_proximal_link.STL" />
      </geometry>
      <material
        name="">
        <color
          rgba="1 1 1 1" />
      </material>
    </visual>
    <collision>
      <origin
        xyz="0 0 0"
        rpy="0 0 0" />
      <geometry>
        <mesh
          filename="../meshes/fourier_hand_12dof_v2/R_pinky_proximal_link.STL" />
      </geometry>
    </collision>
  </link>
  <joint
    name="R_pinky_proximal_joint"
    type="revolute">
    <origin
      xyz="-0.031472 0.0113 -0.099245"
      rpy="-0.26739 1.4622 2.8727" />
    <parent
      link="R_hand_base_link" />
    <child
      link="R_pinky_proximal_link" />
    <axis
      xyz="0 0 1" />
    <limit
      lower="-1.4172"
      upper="0"
      effort="0"
      velocity="0" />
  </joint>
  <link
    name="R_pinky_intermediate_link">
    <inertial>
      <origin
        xyz="0.018249 0.00057564 0"
        rpy="0 0 0" />
      <mass
        value="0.01622" />
      <inertia
        ixx="7.6E-07"
        ixy="2.1E-07"
        ixz="0"
        iyy="2.64E-06"
        iyz="0"
        izz="2.57E-06" />
    </inertial>
    <visual>
      <origin
        xyz="0 0 0"
        rpy="0 0 0" />
      <geometry>
        <mesh
          filename="../meshes/fourier_hand_12dof_v2/R_pinky_intermediate_link.STL" />
      </geometry>
      <material
        name="">
        <color
          rgba="1 1 1 1" />
      </material>
    </visual>
    <collision>
      <origin
        xyz="0 0 0"
        rpy="0 0 0" />
      <geometry>
        <mesh
          filename="../meshes/fourier_hand_12dof_v2/R_pinky_intermediate_link.STL" />
      </geometry>
    </collision>
  </link>
  <joint
    name="R_pinky_intermediate_joint"
    type="revolute">
    <origin
      xyz="0.038963 0.0016981 0"
      rpy="0 0 -0.036802" />
    <parent
      link="R_pinky_proximal_link" />
    <child
      link="R_pinky_intermediate_link" />
    <axis
      xyz="0 0 1" />
    <limit
      lower="-1.4835"
      upper="0"
      effort="0"
      velocity="0" />
  </joint>

  <link name="R_pinky_tip_link">
    <visual>
      <origin
        xyz="0 0 0"
        rpy="0 0 0" />
      <geometry>
        <sphere radius="0.005" />
      </geometry>
      <material name="yellow">
        <color rgba="0.9 1 0 1" />
      </material>
    </visual>
  </link>
  <joint name="R_pinky_tip_joint" type="fixed">
    <parent link="R_pinky_intermediate_link" />
    <child link="R_pinky_tip_link" />
    <origin rpy="0 0 0" xyz="0.038 -0.003 0" />
  </joint>

</robot>
