<?xml version="1.0" encoding="utf-8"?>

<!-- 02282025-alpha-1 -->

<robot
  name="fourier_left_hand_12dof">
  <link
    name="L_hand_base_link">
    <inertial>
      <origin
        xyz="-0.0027 -0.009658 -0.044243"
        rpy="0 0 0" />
      <mass
        value="0.281" />
      <inertia
        ixx="0.000344"
        ixy="-3.26E-06"
        ixz="8.99E-06"
        iyy="0.000474"
        iyz="-1.063E-05"
        izz="0.000217" />
    </inertial>
    <visual>
      <origin
        xyz="0 0 0"
        rpy="0 0 0" />
      <geometry>
        <mesh
          filename="../meshes/fourier_hand_12dof/L_hand_base_link.STL" />
      </geometry>
      <material
        name="">
        <color
          rgba="1 1 1 1" />
      </material>
    </visual>
    <collision>
      <origin
        xyz="0 0 0"
        rpy="0 0 0" />
      <geometry>
        <mesh
          filename="../meshes/fourier_hand_12dof/L_hand_base_link.STL" />
      </geometry>
    </collision>
  </link>

  <link
    name="L_hand_wrist_link">
  </link>
  <joint
    name="L_hand_wrist_joint"
    type="fixed">
    <origin
      xyz="0 0 0"
      rpy="0 0 0" />
    <parent
      link="L_hand_base_link" />
    <child
      link="L_hand_wrist_link" />
    <axis
      xyz="0 0 0" />
  </joint>


  <link
    name="L_thumb_proximal_yaw_link">
    <inertial>
      <origin
        xyz="0.010856 -0.001425 0.000443"
        rpy="0 0 0" />
      <mass
        value="0.04" />
      <inertia
        ixx="4.48E-06"
        ixy="7E-07"
        ixz="-7.4E-07"
        iyy="7.55E-06"
        iyz="6E-8"
        izz="6.88E-06" />
    </inertial>
    <visual>
      <origin
        xyz="0 0 0"
        rpy="0 0 0" />
      <geometry>
        <mesh
          filename="../meshes/fourier_hand_12dof/L_thumb_proximal_yaw_link.STL" />
      </geometry>
      <material
        name="">
        <color
          rgba="1 1 1 1" />
      </material>
    </visual>
    <collision>
      <origin
        xyz="0 0 0"
        rpy="0 0 0" />
      <geometry>
        <mesh
          filename="../meshes/fourier_hand_12dof/L_thumb_proximal_yaw_link.STL" />
      </geometry>
    </collision>
  </link>
  <joint
    name="L_thumb_proximal_yaw_joint"
    type="revolute">
    <origin
      xyz="0.014 -0.012 -0.023196"
      rpy="0 0 0" />
    <parent
      link="L_hand_base_link" />
    <child
      link="L_thumb_proximal_yaw_link" />
    <axis
      xyz="0 0 1" />
    <limit
      lower="-1.4661"
      upper="0"
      effort="0"
      velocity="0" />
  </joint>
  <link
    name="L_thumb_proximal_pitch_link">
    <inertial>
      <origin
        xyz="0.026449 -0.000321 3.22E-06"
        rpy="0 0 0" />
      <mass
        value="0.0415" />
      <inertia
        ixx="5.76E-06"
        ixy="3.7e-7"
        ixz="0"
        iyy="1.33E-05"
        iyz="0"
        izz="1.39E-05" />
    </inertial>
    <visual>
      <origin
        xyz="0 0 0"
        rpy="0 0 0" />
      <geometry>
        <mesh
          filename="../meshes/fourier_hand_12dof/L_thumb_proximal_pitch_link.STL" />
      </geometry>
      <material
        name="">
        <color
          rgba="1 1 1 1" />
      </material>
    </visual>
    <collision>
      <origin
        xyz="0 0 0"
        rpy="0 0 0" />
      <geometry>
        <mesh
          filename="../meshes/fourier_hand_12dof/L_thumb_proximal_pitch_link.STL" />
      </geometry>
    </collision>
  </link>
  <joint
    name="L_thumb_proximal_pitch_joint"
    type="revolute">
    <origin
      xyz="0.034322 -0.0054361 0.001"
      rpy="-1.5708 0 -0.15708" />
    <parent
      link="L_thumb_proximal_yaw_link" />
    <child
      link="L_thumb_proximal_pitch_link" />
    <axis
      xyz="0 0 1" />
    <limit
      lower="0"
      upper="1.274"
      effort="0"
      velocity="0" />
  </joint>
  <link
    name="L_thumb_distal_link">
    <inertial>
      <origin
        xyz="0.0186 -0.00514 1.569E-05"
        rpy="0 0 0" />
      <mass
        value="0.0198" />
      <inertia
        ixx="1.15E-06"
        ixy="-6E-8"
        ixz="0"
        iyy="3.43E-06"
        iyz="0"
        izz="3.24E-06" />
    </inertial>
    <visual>
      <origin
        xyz="0 0 0"
        rpy="0 0 0" />
      <geometry>
        <mesh
          filename="../meshes/fourier_hand_12dof/L_thumb_distal_link.STL" />
      </geometry>
      <material
        name="">
        <color
          rgba="1 1 1 1" />
      </material>
    </visual>
    <collision>
      <origin
        xyz="0 0 0"
        rpy="0 0 0" />
      <geometry>
        <mesh
          filename="../meshes/fourier_hand_12dof/L_thumb_distal_link.STL" />
      </geometry>
    </collision>
  </link>
  <joint
    name="L_thumb_distal_joint"
    type="revolute">
    <origin
      xyz="0.05175 0.0050976 0"
      rpy="0 0 0.071635" />
    <parent
      link="L_thumb_proximal_pitch_link" />
    <child
      link="L_thumb_distal_link" />
    <axis
      xyz="0 0 1" />
    <limit
      lower="0"
      upper="1.3614"
      effort="0"
      velocity="0" />
  </joint>

  <link name="L_thumb_tip_link">
    <visual>
      <origin
        xyz="0 0 0"
        rpy="0 0 0" />
      <geometry>
        <sphere radius="0.005" />
      </geometry>
      <material name="yellow">
        <color rgba="0.9 1 0 1" />
      </material>
    </visual>
  </link>
  <joint name="L_thumb_tip_joint" type="fixed">
    <parent link="L_thumb_distal_link" />
    <child link="L_thumb_tip_link" />
    <origin rpy="0 0 0" xyz="0.035 -0.001 0" />
  </joint>


  <link
    name="L_index_metacarpal_link">
    <inertial>
      <origin
        xyz="-0.00912 0.00394 0"
        rpy="0 0 0" />
      <mass
        value="0.0321" />
      <inertia
        ixx="1.09E-06"
        ixy="1.85E-06"
        ixz="0"
        iyy="7.7E-06"
        iyz="0"
        izz="7.94E-06" />
    </inertial>
    <visual>
      <origin
        xyz="0 0 0"
        rpy="0 0 0" />
      <geometry>
        <mesh
          filename="../meshes/fourier_hand_12dof/L_index_metacarpal_link.STL" />
      </geometry>
      <material
        name="">
        <color
          rgba="1 1 1 1" />
      </material>
    </visual>
    <collision>
      <origin
        xyz="0 0 0"
        rpy="0 0 0" />
      <geometry>
        <mesh
          filename="../meshes/fourier_hand_12dof/L_index_metacarpal_link.STL" />
      </geometry>
    </collision>
  </link>
  <joint
    name="L_index_metacarpal_joint"
    type="revolute">
    <origin
      xyz="0.0305 -0.0118 -0.088496"
      rpy="3.1416 1.4946 0" />
    <parent
      link="L_hand_base_link" />
    <child
      link="L_index_metacarpal_link" />
    <axis
      xyz="0 1 0" />
    <limit
      lower="-0.0524"
      upper="0.2618"
      effort="0"
      velocity="0" />
  </joint>
  <link
    name="L_index_proximal_link">
    <inertial>
      <origin
        xyz="0.01736 0.0045 0"
        rpy="0 0 0" />
      <mass
        value="0.0358" />
      <inertia
        ixx="3.91E-06"
        ixy="-2.7E-7"
        ixz="0"
        iyy="7.43E-06"
        iyz="0"
        izz="7.77E-06" />
    </inertial>
    <visual>
      <origin
        xyz="0 0 0"
        rpy="0 0 0" />
      <geometry>
        <mesh
          filename="../meshes/fourier_hand_12dof/L_index_proximal_link.STL" />
      </geometry>
      <material
        name="">
        <color
          rgba="1 1 1 1" />
      </material>
    </visual>
    <collision>
      <origin
        xyz="0 0 0"
        rpy="0 0 0" />
      <geometry>
        <mesh
          filename="../meshes/fourier_hand_12dof/L_index_proximal_link.STL" />
      </geometry>
    </collision>
  </link>
  <joint
    name="L_index_proximal_joint"
    type="revolute">
    <origin
      xyz="0.012 -0.0005 0"
      rpy="3.1416 0 0" />
    <parent
      link="L_index_metacarpal_link" />
    <child
      link="L_index_proximal_link" />
    <axis
      xyz="0 0 1" />
    <limit
      lower="-1.5185"
      upper="0"
      effort="0"
      velocity="0" />
  </joint>
  <link
    name="L_index_intermediate_link">
    <inertial>
      <origin
        xyz="0.02243 0.002908 1.624e-5"
        rpy="0 0 0" />
      <mass
        value="0.0199" />
      <inertia
        ixx="8.4E-7"
        ixy="4E-8"
        ixz="1E-8"
        iyy="4.82E-6"
        iyz="0"
        izz="4.72E-6" />
    </inertial>
    <visual>
      <origin
        xyz="0 0 0"
        rpy="0 0 0" />
      <geometry>
        <mesh
          filename="../meshes/fourier_hand_12dof/L_index_intermediate_link.STL" />
      </geometry>
      <material
        name="">
        <color
          rgba="1 1 1 1" />
      </material>
    </visual>
    <collision>
      <origin
        xyz="0 0 0"
        rpy="0 0 0" />
      <geometry>
        <mesh
          filename="../meshes/fourier_hand_12dof/L_index_intermediate_link.STL" />
      </geometry>
    </collision>
  </link>
  <joint
    name="L_index_intermediate_joint"
    type="revolute">
    <origin
      xyz="0.038948 0.0020202 0"
      rpy="0 0 -0.19585" />
    <parent
      link="L_index_proximal_link" />
    <child
      link="L_index_intermediate_link" />
    <axis
      xyz="0 0 1" />
    <limit
      lower="-1.5708"
      upper="0"
      effort="0"
      velocity="0" />
  </joint>

  <link name="L_index_tip_link">
    <visual>
      <origin
        xyz="0 0 0"
        rpy="0 0 0" />
      <geometry>
        <sphere radius="0.005" />
      </geometry>
      <material name="yellow">
        <color rgba="0.9 1 0 1" />
      </material>
    </visual>
  </link>
  <joint name="L_index_tip_joint" type="fixed">
    <parent link="L_index_intermediate_link" />
    <child link="L_index_tip_link" />
    <origin rpy="0 0 0" xyz="0.047 0.001 0" />
  </joint>

  <link
    name="L_middle_proximal_link">
    <inertial>
      <origin
        xyz="0.017361 0.0045 0"
        rpy="0 0 0" />
      <mass
        value="0.0358" />
      <inertia
        ixx="3.91E-06"
        ixy="-2.7E-7"
        ixz="0"
        iyy="7.43E-06"
        iyz="0"
        izz="7.77E-06" />
    </inertial>
    <visual>
      <origin
        xyz="0 0 0"
        rpy="0 0 0" />
      <geometry>
        <mesh
          filename="../meshes/fourier_hand_12dof/L_middle_proximal_link.STL" />
      </geometry>
      <material
        name="">
        <color
          rgba="1 1 1 1" />
      </material>
    </visual>
    <collision>
      <origin
        xyz="0 0 0"
        rpy="0 0 0" />
      <geometry>
        <mesh
          filename="../meshes/fourier_hand_12dof/L_middle_proximal_link.STL" />
      </geometry>
    </collision>
  </link>
  <joint
    name="L_middle_proximal_joint"
    type="revolute">
    <origin
      xyz="0.0095 -0.0113 -0.10005"
      rpy="0 1.5708 0" />
    <parent
      link="L_hand_base_link" />
    <child
      link="L_middle_proximal_link" />
    <axis
      xyz="0 0 1" />
    <limit
      lower="-1.5185"
      upper="0"
      effort="0"
      velocity="0" />
  </joint>
  <link
    name="L_middle_intermediate_link">
    <inertial>
      <origin
        xyz="0.0247 0.00323 1.39E-5"
        rpy="0 0 0" />
      <mass
        value="0.0234" />
      <inertia
        ixx="1.01E-6"
        ixy="-4E-8"
        ixz="1E-8"
        iyy="6.94E-6"
        iyz="0"
        izz="6.82E-6" />
    </inertial>
    <visual>
      <origin
        xyz="0 0 0"
        rpy="0 0 0" />
      <geometry>
        <mesh
          filename="../meshes/fourier_hand_12dof/L_middle_intermediate_link.STL" />
      </geometry>
      <material
        name="">
        <color
          rgba="1 1 1 1" />
      </material>
    </visual>
    <collision>
      <origin
        xyz="0 0 0"
        rpy="0 0 0" />
      <geometry>
        <mesh
          filename="../meshes/fourier_hand_12dof/L_middle_intermediate_link.STL" />
      </geometry>
    </collision>
  </link>
  <joint
    name="L_middle_intermediate_joint"
    type="revolute">
    <origin
      xyz="0.038948 0.0020202 0"
      rpy="0 0 -0.19218" />
    <parent
      link="L_middle_proximal_link" />
    <child
      link="L_middle_intermediate_link" />
    <axis
      xyz="0 0 1" />
    <limit
      lower="-1.5708"
      upper="0"
      effort="0"
      velocity="0" />
  </joint>

  <link name="L_middle_tip_link">
    <visual>
      <origin
        xyz="0 0 0"
        rpy="0 0 0" />
      <geometry>
        <sphere radius="0.005" />
      </geometry>
      <material name="yellow">
        <color rgba="0.9 1 0 1" />
      </material>
    </visual>
  </link>
  <joint name="L_middle_tip_joint" type="fixed">
    <parent link="L_middle_intermediate_link" />
    <child link="L_middle_tip_link" />
    <origin rpy="0 0 0" xyz="0.055 0.0012 0" />
  </joint>


  <link
    name="L_ring_proximal_link">
    <inertial>
      <origin
        xyz="0.017361 0.0045 0"
        rpy="0 0 0" />
      <mass
        value="0.035778" />
      <inertia
        ixx="3.91E-06"
        ixy="-2.7E-7"
        ixz="0"
        iyy="7.4E-06"
        iyz="0"
        izz="7.7E-06" />
    </inertial>
    <visual>
      <origin
        xyz="0 0 0"
        rpy="0 0 0" />
      <geometry>
        <mesh
          filename="../meshes/fourier_hand_12dof/L_ring_proximal_link.STL" />
      </geometry>
      <material
        name="">
        <color
          rgba="1 1 1 1" />
      </material>
    </visual>
    <collision>
      <origin
        xyz="0 0 0"
        rpy="0 0 0" />
      <geometry>
        <mesh
          filename="../meshes/fourier_hand_12dof/L_ring_proximal_link.STL" />
      </geometry>
    </collision>
  </link>
  <joint
    name="L_ring_proximal_joint"
    type="revolute">
    <origin
      xyz="-0.010987 -0.0113 -0.10003"
      rpy="-3.1416 1.5184 -3.1416" />
    <parent
      link="L_hand_base_link" />
    <child
      link="L_ring_proximal_link" />
    <axis
      xyz="0 0 1" />
    <limit
      lower="-1.5185"
      upper="0"
      effort="0"
      velocity="0" />
  </joint>
  <link
    name="L_ring_intermediate_link">
    <inertial>
      <origin
        xyz="0.02243 0.002908 1.624E-5"
        rpy="0 0 0" />
      <mass
        value="0.0199" />
      <inertia
        ixx="8.4E-7"
        ixy="4E-8"
        ixz="1E-8"
        iyy="4.82E-6"
        iyz="0"
        izz="4.72E-6" />
    </inertial>
    <visual>
      <origin
        xyz="0 0 0"
        rpy="0 0 0" />
      <geometry>
        <mesh
          filename="../meshes/fourier_hand_12dof/L_ring_intermediate_link.STL" />
      </geometry>
      <material
        name="">
        <color
          rgba="1 1 1 1" />
      </material>
    </visual>
    <collision>
      <origin
        xyz="0 0 0"
        rpy="0 0 0" />
      <geometry>
        <mesh
          filename="../meshes/fourier_hand_12dof/L_ring_intermediate_link.STL" />
      </geometry>
    </collision>
  </link>
  <joint
    name="L_ring_intermediate_joint"
    type="revolute">
    <origin
      xyz="0.038948 0.0020202 0"
      rpy="0 0 -0.19585" />
    <parent
      link="L_ring_proximal_link" />
    <child
      link="L_ring_intermediate_link" />
    <axis
      xyz="0 0 1" />
    <limit
      lower="-1.5708"
      upper="0"
      effort="0"
      velocity="0" />
  </joint>

  <link name="L_ring_tip_link">
    <visual>
      <origin
        xyz="0 0 0"
        rpy="0 0 0" />
      <geometry>
        <sphere radius="0.005" />
      </geometry>
      <material name="green">
        <color rgba="0.9 1 0 1" />
      </material>
    </visual>
  </link>
  <joint name="L_ring_tip_joint" type="fixed">
    <parent link="L_ring_intermediate_link" />
    <child link="L_ring_tip_link" />
    <origin rpy="0 0 0" xyz="0.045 0.001 0" />
  </joint>


  <link
    name="L_pinky_proximal_link">
    <inertial>
      <origin
        xyz="0.017361 0.0045 0"
        rpy="0 0 0" />
      <mass
        value="0.0358" />
      <inertia
        ixx="3.91E-06"
        ixy="-2.7E-7"
        ixz="0"
        iyy="7.4E-06"
        iyz="0"
        izz="7.77E-06" />
    </inertial>
    <visual>
      <origin
        xyz="0 0 0"
        rpy="0 0 0" />
      <geometry>
        <mesh
          filename="../meshes/fourier_hand_12dof/L_pinky_proximal_link.STL" />
      </geometry>
      <material
        name="">
        <color
          rgba="1 1 1 1" />
      </material>
    </visual>
    <collision>
      <origin
        xyz="0 0 0"
        rpy="0 0 0" />
      <geometry>
        <mesh
          filename="../meshes/fourier_hand_12dof/L_pinky_proximal_link.STL" />
      </geometry>
    </collision>
  </link>
  <joint
    name="L_pinky_proximal_joint"
    type="revolute">
    <origin
      xyz="-0.031472 -0.0113 -0.099245"
      rpy="-3.1416 1.4661 -3.1416" />
    <parent
      link="L_hand_base_link" />
    <child
      link="L_pinky_proximal_link" />
    <axis
      xyz="0 0 1" />
    <limit
      lower="-1.5185"
      upper="0"
      effort="0"
      velocity="0" />
  </joint>
  <link
    name="L_pinky_intermediate_link">
    <inertial>
      <origin
        xyz="0.01875 0.00296 5.23E-6"
        rpy="0 0 0" />
      <mass
        value="0.00812" />
      <inertia
        ixx="6.7E-7"
        ixy="5E-8"
        ixz="1E-8"
        iyy="2.69E-06"
        iyz="0"
        izz="2.6E-06" />
    </inertial>
    <visual>
      <origin
        xyz="0 0 0"
        rpy="0 0 0" />
      <geometry>
        <mesh
          filename="../meshes/fourier_hand_12dof/L_pinky_intermediate_link.STL" />
      </geometry>
      <material
        name="">
        <color
          rgba="1 1 1 1" />
      </material>
    </visual>
    <collision>
      <origin
        xyz="0 0 0"
        rpy="0 0 0" />
      <geometry>
        <mesh
          filename="../meshes/fourier_hand_12dof/L_pinky_intermediate_link.STL" />
      </geometry>
    </collision>
  </link>
  <joint
    name="L_pinky_intermediate_joint"
    type="revolute">
    <origin
      xyz="0.038948 0.0020202 0"
      rpy="0 -0.0013299 -0.20067" />
    <parent
      link="L_pinky_proximal_link" />
    <child
      link="L_pinky_intermediate_link" />
    <axis
      xyz="0.0013299 0 1" />
    <limit
      lower="-1.5708"
      upper="0"
      effort="0"
      velocity="0" />
  </joint>

  <link name="L_pinky_tip_link">
    <visual>
      <origin
        xyz="0 0 0"
        rpy="0 0 0" />
      <geometry>
        <sphere radius="0.005" />
      </geometry>
      <material name="yellow">
        <color rgba="0.9 1 0 1" />
      </material>
    </visual>
  </link>
  <joint name="L_pinky_tip_joint" type="fixed">
    <parent link="L_pinky_intermediate_link" />
    <child link="L_pinky_tip_link" />
    <origin rpy="0 0 0" xyz="0.038 0.001 0" />
  </joint>


</robot>
