<?xml version="1.0" encoding="utf-8"?>

<!-- 02282025-alpha-1 -->

<robot
  name="GR2T2v2_fourier_hand_12dof">
  <link
    name="base_link">
    <inertial>
      <origin
        xyz="-0.0030357 6.968E-05 -0.087284"
        rpy="0 0 0" />
      <mass
        value="6.6598" />
      <inertia
        ixx="0.048356"
        ixy="-1.314E-05"
        ixz="0.00041517"
        iyy="0.030781"
        iyz="-3.242E-05"
        izz="0.041191" />
    </inertial>
    <visual>
      <origin
        xyz="0 0 0"
        rpy="0 0 0" />
      <geometry>
        <mesh
          filename="../meshes/gr2t2v2/base_link.STL" />
      </geometry>
      <material
        name="">
        <color
          rgba="1 1 1 1" />
      </material>
    </visual>
    <collision>
      <origin
        xyz="0 0.125 0.01"
        rpy="0 0 0" />
      <geometry>
        <box size="0.18 0.06 0.02" />
      </geometry>
    </collision>
    <collision>
      <origin
        xyz="0 -0.125 0.01"
        rpy="0 0 0" />
      <geometry>
        <box size="0.18 0.06 0.02" />
      </geometry>
    </collision>
    <collision>
      <origin
        xyz="-0.03 0 -0.08"
        rpy="1.57 0 0" />
      <geometry>
        <cylinder radius="0.1" length="0.17" />
      </geometry>
    </collision>
  </link>
  <link
    name="waist_yaw_link">
    <inertial>
      <origin
        xyz="-2.017E-05 8.88E-05 0.024104"
        rpy="0 0 0" />
      <mass
        value="0.67252" />
      <inertia
        ixx="0.0010622"
        ixy="9E-08"
        ixz="-4.3E-07"
        iyy="0.0010624"
        iyz="3.7E-07"
        izz="0.00059099" />
    </inertial>
    <visual>
      <origin
        xyz="0 0 0"
        rpy="0 0 0" />
      <geometry>
        <mesh
          filename="../meshes/gr2t2v2/waist_yaw_link.STL" />
      </geometry>
      <material
        name="">
        <color
          rgba="1 1 1 1" />
      </material>
    </visual>
    <!-- <collision>
      <origin
        xyz="0 0 0"
        rpy="0 0 0" />
      <geometry>
        <mesh
          filename="../meshes/gr2t2v2/waist_yaw_link.STL" />
      </geometry>
    </collision> -->
  </link>
  <joint
    name="waist_yaw_joint"
    type="revolute">
    <origin
      xyz="0 0 -0.0159"
      rpy="0 0 0" />
    <parent
      link="base_link" />
    <child
      link="waist_yaw_link" />
    <axis
      xyz="0 0 1" />
    <limit
      lower="-2.618"
      upper="2.618"
      effort="74.45"
      velocity="7.7568" />
  </joint>
  <link
    name="torso_link">
    <inertial>
      <origin
        xyz="-0.0054214 0.0010624 -0.12326"
        rpy="0 0 0" />
      <mass
        value="14.058" />
      <inertia
        ixx="0.2545"
        ixy="0.0001127"
        ixz="-0.0023"
        iyy="0.21565"
        iyz="0.00034939"
        izz="0.1107" />
    </inertial>
    <visual>
      <origin
        xyz="0 0 0"
        rpy="0 0 0" />
      <geometry>
        <mesh
          filename="../meshes/gr2t2v2/torso_link.STL" />
      </geometry>
      <material
        name="">
        <color
          rgba="1 1 1 1" />
      </material>
    </visual>
    <collision>
      <origin
        xyz="0 0 -0.13"
        rpy="0 0 0" />
      <geometry>
        <cylinder radius="0.15" length="0.3" />
      </geometry>
    </collision>
  </link>
  <joint
    name="torso_joint"
    type="fixed">
    <origin
      xyz="0 0 0.39681"
      rpy="0 0 0" />
    <parent
      link="waist_yaw_link" />
    <child
      link="torso_link" />
    <axis
      xyz="0 0 0" />
  </joint>
  <link
    name="head_yaw_link">
    <inertial>
      <origin
        xyz="0 0.0099543 0.0065646"
        rpy="0 0 0" />
      <mass
        value="0.1402" />
      <inertia
        ixx="0.00012944"
        ixy="0"
        ixz="0"
        iyy="0.00010676"
        iyz="-3.991E-05"
        izz="4.821E-05" />
    </inertial>
    <visual>
      <origin
        xyz="0 0 0"
        rpy="0 0 0" />
      <geometry>
        <mesh
          filename="../meshes/gr2t2v2/head_yaw_link.STL" />
      </geometry>
      <material
        name="">
        <color
          rgba="1 1 1 1" />
      </material>
    </visual>
    <!-- <collision>
      <origin
        xyz="0 0 0"
        rpy="0 0 0" />
      <geometry>
        <mesh
          filename="../meshes/gr2t2v2/head_yaw_link.STL" />
      </geometry>
    </collision> -->
  </link>
  <joint
    name="head_yaw_joint"
    type="revolute">
    <origin
      xyz="0.001 0 0.11061"
      rpy="0 0 0" />
    <parent
      link="torso_link" />
    <child
      link="head_yaw_link" />
    <axis
      xyz="0 0 1" />
    <limit
      lower="-1.3963"
      upper="1.3963"
      effort="17.325"
      velocity="9.1627" />
  </joint>
  <link
    name="head_pitch_link">
    <inertial>
      <origin
        xyz="0.031582 0.0012059 0.072239"
        rpy="0 0 0" />
      <mass
        value="1.6096" />
      <inertia
        ixx="0.0077257"
        ixy="-1.346E-05"
        ixz="-0.00055988"
        iyy="0.010424"
        iyz="0.00010711"
        izz="0.0060799" />
    </inertial>
    <visual>
      <origin
        xyz="0 0 0"
        rpy="0 0 0" />
      <geometry>
        <mesh
          filename="../meshes/gr2t2v2/head_pitch_link.STL" />
      </geometry>
      <material
        name="">
        <color
          rgba="1 1 1 1" />
      </material>
    </visual>
    <collision>
      <origin
        xyz="0.02 0 0.07"
        rpy="0 0 0" />
      <geometry>
        <sphere radius="0.09" />
      </geometry>
    </collision>
  </link>
  <joint
    name="head_pitch_joint"
    type="revolute">
    <origin
      xyz="0 0 0.044185"
      rpy="0 0 0" />
    <parent
      link="head_yaw_link" />
    <child
      link="head_pitch_link" />
    <axis
      xyz="0 1 0" />
    <limit
      lower="-0.5236"
      upper="0.5236"
      effort="17.325"
      velocity="9.1627" />
  </joint>
  <link
    name="camera_link">
    <inertial>
      <origin
        xyz="0 0 0"
        rpy="0 0 0" />
      <mass
        value="0" />
      <inertia
        ixx="0"
        ixy="0"
        ixz="0"
        iyy="0"
        iyz="0"
        izz="0" />
    </inertial>

  </link>
  <joint
    name="camera_joint"
    type="fixed">
    <origin
      xyz="0.11296 0 0.09815"
      rpy="0 0 0" />
    <parent
      link="head_pitch_link" />
    <child
      link="camera_link" />
    <axis
      xyz="0 0 0" />
  </joint>
  <link
    name="left_upper_arm_pitch_link">
    <inertial>
      <origin
        xyz="0.0022312 0.040265 3.797E-05"
        rpy="0 0 0" />
      <mass
        value="1.3432" />
      <inertia
        ixx="0.0031811"
        ixy="-7.306E-05"
        ixz="-1.5E-07"
        iyy="0.0012561"
        iyz="9E-08"
        izz="0.0030442" />
    </inertial>
    <visual>
      <origin
        xyz="0 0 0"
        rpy="0 0 0" />
      <geometry>
        <mesh
          filename="../meshes/gr2t2v2/left_upper_arm_pitch_link.STL" />
      </geometry>
      <material
        name="">
        <color
          rgba="1 1 1 1" />
      </material>
    </visual>
    <!-- <collision>
      <origin
        xyz="0 0 0"
        rpy="0 0 0" />
      <geometry>
        <mesh
          filename="../meshes/gr2t2v2/left_upper_arm_pitch_link.STL" />
      </geometry>
    </collision> -->
  </link>
  <joint
    name="left_shoulder_pitch_joint"
    type="revolute">
    <origin
      xyz="0 0.15115 0"
      rpy="0 0 0" />
    <parent
      link="torso_link" />
    <child
      link="left_upper_arm_pitch_link" />
    <axis
      xyz="0 1 0" />
    <limit
      lower="-2.9671"
      upper="2.9671"
      effort="74.45"
      velocity="7.7568" />
  </joint>
  <link
    name="left_upper_arm_roll_link">
    <inertial>
      <origin
        xyz="0.0087432 0.0022878 -0.038787"
        rpy="0 0 0" />
      <mass
        value="0.96142" />
      <inertia
        ixx="0.0026111"
        ixy="1.105E-05"
        ixz="-0.00033468"
        iyy="0.0028017"
        iyz="2.91E-06"
        izz="0.00091191" />
    </inertial>
    <visual>
      <origin
        xyz="0 0 0"
        rpy="0 0 0" />
      <geometry>
        <mesh
          filename="../meshes/gr2t2v2/left_upper_arm_roll_link.STL" />
      </geometry>
      <material
        name="">
        <color
          rgba="1 1 1 1" />
      </material>
    </visual>
    <collision>
      <origin
        xyz="0 0 0"
        rpy="0 0 0" />
      <geometry>
        <sphere radius="0.045" />
      </geometry>
    </collision>
  </link>
  <joint
    name="left_shoulder_roll_joint"
    type="revolute">
    <origin
      xyz="0 0.078848 0"
      rpy="0 0 0" />
    <parent
      link="left_upper_arm_pitch_link" />
    <child
      link="left_upper_arm_roll_link" />
    <axis
      xyz="1 0 0" />
    <limit
      lower="-0.5236"
      upper="2.7925"
      effort="74.45"
      velocity="7.7568" />
  </joint>
  <link
    name="left_upper_arm_yaw_link">
    <inertial>
      <origin
        xyz="-0.00056161 0.0012137 -0.091108"
        rpy="0 0 0" />
      <mass
        value="1.3181" />
      <inertia
        ixx="0.0067903"
        ixy="3.2E-07"
        ixz="-5.12E-06"
        iyy="0.0068059"
        iyz="9.238E-05"
        izz="0.0010853" />
    </inertial>
    <visual>
      <origin
        xyz="0 0 0"
        rpy="0 0 0" />
      <geometry>
        <mesh
          filename="../meshes/gr2t2v2/left_upper_arm_yaw_link.STL" />
      </geometry>
      <material
        name="">
        <color
          rgba="1 1 1 1" />
      </material>
    </visual>
    <collision>
      <origin
        xyz="0 0 -0.05"
        rpy="0 0 0" />
      <geometry>
        <cylinder radius="0.04" length="0.10" />
      </geometry>
    </collision>
  </link>
  <joint
    name="left_shoulder_yaw_joint"
    type="revolute">
    <origin
      xyz="0 0 -0.09438"
      rpy="0 0 0" />
    <parent
      link="left_upper_arm_roll_link" />
    <child
      link="left_upper_arm_yaw_link" />
    <axis
      xyz="0 0 1" />
    <limit
      lower="-1.8326"
      upper="1.8326"
      effort="42.75"
      velocity="6.283" />
  </joint>
  <link
    name="left_lower_arm_pitch_link">
    <inertial>
      <origin
        xyz="-0.0014862 0.006973 -0.021097"
        rpy="0 0 0" />
      <mass
        value="0.45807" />
      <inertia
        ixx="0.00068974"
        ixy="-3.65E-06"
        ixz="-2.99E-06"
        iyy="0.00057464"
        iyz="-6.575E-05"
        izz="0.00038897" />
    </inertial>
    <visual>
      <origin
        xyz="0 0 0"
        rpy="0 0 0" />
      <geometry>
        <mesh
          filename="../meshes/gr2t2v2/left_lower_arm_pitch_link.STL" />
      </geometry>
      <material
        name="">
        <color
          rgba="1 1 1 1" />
      </material>
    </visual>
    <!-- <collision>
      <origin
        xyz="0 0 0"
        rpy="0 0 0" />
      <geometry>
        <mesh
          filename="../meshes/gr2t2v2/left_lower_arm_pitch_link.STL" />
      </geometry>
    </collision> -->
  </link>
  <joint
    name="left_elbow_pitch_joint"
    type="revolute">
    <origin
      xyz="0 0 -0.16111"
      rpy="0 -0.3926 0" />
    <parent
      link="left_upper_arm_yaw_link" />
    <child
      link="left_lower_arm_pitch_link" />
    <axis
      xyz="0 1 0" />
    <limit
      lower="-1.5272"
      upper="0.47997"
      effort="42.75"
      velocity="6.283" />
  </joint>
  <link
    name="left_hand_yaw_link">
    <inertial>
      <origin
        xyz="0.00027991 0.0038031 -0.062955"
        rpy="0 0 0" />
      <mass
        value="1.0855" />
      <inertia
        ixx="0.0023598"
        ixy="-9.31E-06"
        ixz="2.063E-05"
        iyy="0.002234"
        iyz="0.00013994"
        izz="0.00088838" />
    </inertial>
    <visual>
      <origin
        xyz="0 0 0"
        rpy="0 0 0" />
      <geometry>
        <mesh
          filename="../meshes/gr2t2v2/left_hand_yaw_link.STL" />
      </geometry>
      <material
        name="">
        <color
          rgba="1 1 1 1" />
      </material>
    </visual>
    <collision>
      <origin
        xyz="0 0 -0.05"
        rpy="0 0 0" />
      <geometry>
        <cylinder radius="0.045" length="0.115" />
      </geometry>
    </collision>
  </link>
  <joint
    name="left_wrist_yaw_joint"
    type="revolute">
    <origin
      xyz="0 0 -0.058525"
      rpy="0 0 0" />
    <parent
      link="left_lower_arm_pitch_link" />
    <child
      link="left_hand_yaw_link" />
    <axis
      xyz="0 0 1" />
    <limit
      lower="-1.8326"
      upper="1.8326"
      effort="17.325"
      velocity="9.1627" />
  </joint>
  <link
    name="left_hand_pitch_link">
    <inertial>
      <origin
        xyz="0.0038604 2.7474E-05 2.9411E-06"
        rpy="0 0 0" />
      <mass
        value="0.45716" />
      <inertia
        ixx="0.00021943"
        ixy="-3.7E-07"
        ixz="-8.6975E-08"
        iyy="0.00022813"
        iyz="-2.1E-07"
        izz="0.00023483" />
    </inertial>
    <visual>
      <origin
        xyz="0 0 0"
        rpy="0 0 0" />
      <geometry>
        <mesh
          filename="../meshes/gr2t2v2/left_hand_pitch_link.STL" />
      </geometry>
      <material
        name="">
        <color
          rgba="1 1 1 1" />
      </material>
    </visual>
    <!-- <collision>
      <origin
        xyz="0 0 0"
        rpy="0 0 0" />
      <geometry>
        <mesh
          filename="../meshes/gr2t2v2/left_hand_pitch_link.STL" />
      </geometry>
    </collision> -->
  </link>
  <joint
    name="left_wrist_pitch_joint"
    type="revolute">
    <origin
      xyz="0 0 -0.16102"
      rpy="0 0 0" />
    <parent
      link="left_hand_yaw_link" />
    <child
      link="left_hand_pitch_link" />
    <axis
      xyz="0 1 0" />
    <limit
      lower="-0.61087"
      upper="0.61087"
      effort="17.325"
      velocity="9.1627" />
  </joint>
  <link
    name="left_hand_roll_link">
    <inertial>
      <origin
        xyz="0.0087325 -2.8386E-05 -0.015719"
        rpy="0 0 0" />
      <mass
        value="0.20259" />
      <inertia
        ixx="0.0001134"
        ixy="-1.8583E-08"
        ixz="-2.4468E-05"
        iyy="0.00019338"
        iyz="-6.0314E-08"
        izz="0.0001471" />
    </inertial>
    <visual>
      <origin
        xyz="0 0 0"
        rpy="0 0 0" />
      <geometry>
        <mesh
          filename="../meshes/gr2t2v2/left_hand_roll_link.STL" />
      </geometry>
      <material
        name="">
        <color
          rgba="1 1 1 1" />
      </material>
    </visual>
    <!-- <collision>
      <origin
        xyz="0 0 0"
        rpy="0 0 0" />
      <geometry>
        <mesh
          filename="../meshes/gr2t2v2/left_hand_roll_link.STL" />
      </geometry>
    </collision> -->
  </link>
  <joint
    name="left_wrist_roll_joint"
    type="revolute">
    <origin
      xyz="0 0 0"
      rpy="0 0 0" />
    <parent
      link="left_hand_pitch_link" />
    <child
      link="left_hand_roll_link" />
    <axis
      xyz="1 0 0" />
    <limit
      lower="-0.95993"
      upper="0.95993"
      effort="17.325"
      velocity="9.1627" />
  </joint>
  <link
    name="left_end_effector_link">
  </link>
  <joint
    name="left_end_effector_joint"
    type="fixed">
    <origin
      xyz="0 0 -0.045"
      rpy="0 0 0" />
    <parent
      link="left_hand_roll_link" />
    <child
      link="left_end_effector_link" />
    <axis
      xyz="0 0 0" />
  </joint>

  <link
    name="L_hand_base_link">
    <inertial>
      <origin
        xyz="-0.0027 -0.009658 -0.044243"
        rpy="0 0 0" />
      <mass
        value="0.281" />
      <inertia
        ixx="0.000344"
        ixy="-3.26E-06"
        ixz="8.99E-06"
        iyy="0.000474"
        iyz="-1.063E-05"
        izz="0.000217" />
    </inertial>
    <visual>
      <origin
        xyz="0 0 0"
        rpy="0 0 0" />
      <geometry>
        <mesh
          filename="../meshes/fourier_hand_12dof/L_hand_base_link.STL" />
      </geometry>
      <material
        name="">
        <color
          rgba="1 1 1 1" />
      </material>
    </visual>
    <collision>
      <origin
        xyz="0 0 0"
        rpy="0 0 0" />
      <geometry>
        <mesh
          filename="../meshes/fourier_hand_12dof/L_hand_base_link.STL" />
      </geometry>
    </collision>
  </link>
  <joint
    name="L_hand_base_joint"
    type="fixed">
    <origin
      xyz="0 0 0"
      rpy="0 0 0" />
    <parent
      link="left_end_effector_link" />
    <child
      link="L_hand_base_link" />
    <axis
      xyz="0 0 0" />
  </joint>
  <link
    name="L_thumb_proximal_yaw_link">
    <inertial>
      <origin
        xyz="0.010856 -0.001425 0.000443"
        rpy="0 0 0" />
      <mass
        value="0.04" />
      <inertia
        ixx="4.48E-06"
        ixy="7E-07"
        ixz="-7.4E-07"
        iyy="7.55E-06"
        iyz="6E-8"
        izz="6.88E-06" />
    </inertial>
    <visual>
      <origin
        xyz="0 0 0"
        rpy="0 0 0" />
      <geometry>
        <mesh
          filename="../meshes/fourier_hand_12dof/L_thumb_proximal_yaw_link.STL" />
      </geometry>
      <material
        name="">
        <color
          rgba="1 1 1 1" />
      </material>
    </visual>
    <collision>
      <origin
        xyz="0 0 0"
        rpy="0 0 0" />
      <geometry>
        <mesh
          filename="../meshes/fourier_hand_12dof/L_thumb_proximal_yaw_link.STL" />
      </geometry>
    </collision>
  </link>
  <joint
    name="L_thumb_proximal_yaw_joint"
    type="revolute">
    <origin
      xyz="0.014 -0.012 -0.023196"
      rpy="0 0 0" />
    <parent
      link="L_hand_base_link" />
    <child
      link="L_thumb_proximal_yaw_link" />
    <axis
      xyz="0 0 1" />
    <limit
      lower="-1.4661"
      upper="0"
      effort="0"
      velocity="0" />
  </joint>
  <link
    name="L_thumb_proximal_pitch_link">
    <inertial>
      <origin
        xyz="0.026449 -0.000321 3.22E-06"
        rpy="0 0 0" />
      <mass
        value="0.0415" />
      <inertia
        ixx="5.76E-06"
        ixy="3.7e-7"
        ixz="0"
        iyy="1.33E-05"
        iyz="0"
        izz="1.39E-05" />
    </inertial>
    <visual>
      <origin
        xyz="0 0 0"
        rpy="0 0 0" />
      <geometry>
        <mesh
          filename="../meshes/fourier_hand_12dof/L_thumb_proximal_pitch_link.STL" />
      </geometry>
      <material
        name="">
        <color
          rgba="1 1 1 1" />
      </material>
    </visual>
    <collision>
      <origin
        xyz="0 0 0"
        rpy="0 0 0" />
      <geometry>
        <mesh
          filename="../meshes/fourier_hand_12dof/L_thumb_proximal_pitch_link.STL" />
      </geometry>
    </collision>
  </link>
  <joint
    name="L_thumb_proximal_pitch_joint"
    type="revolute">
    <origin
      xyz="0.034322 -0.0054361 0.001"
      rpy="-1.5708 0 -0.15708" />
    <parent
      link="L_thumb_proximal_yaw_link" />
    <child
      link="L_thumb_proximal_pitch_link" />
    <axis
      xyz="0 0 1" />
    <limit
      lower="0"
      upper="1.274"
      effort="0"
      velocity="0" />
  </joint>
  <link
    name="L_thumb_distal_link">
    <inertial>
      <origin
        xyz="0.0186 -0.00514 1.569E-05"
        rpy="0 0 0" />
      <mass
        value="0.0198" />
      <inertia
        ixx="1.15E-06"
        ixy="-6E-8"
        ixz="0"
        iyy="3.43E-06"
        iyz="0"
        izz="3.24E-06" />
    </inertial>
    <visual>
      <origin
        xyz="0 0 0"
        rpy="0 0 0" />
      <geometry>
        <mesh
          filename="../meshes/fourier_hand_12dof/L_thumb_distal_link.STL" />
      </geometry>
      <material
        name="">
        <color
          rgba="1 1 1 1" />
      </material>
    </visual>
    <collision>
      <origin
        xyz="0 0 0"
        rpy="0 0 0" />
      <geometry>
        <mesh
          filename="../meshes/fourier_hand_12dof/L_thumb_distal_link.STL" />
      </geometry>
    </collision>
  </link>
  <joint
    name="L_thumb_distal_joint"
    type="revolute">
    <origin
      xyz="0.05175 0.0050976 0"
      rpy="0 0 0.071635" />
    <parent
      link="L_thumb_proximal_pitch_link" />
    <child
      link="L_thumb_distal_link" />
    <axis
      xyz="0 0 1" />
    <limit
      lower="0"
      upper="1.3614"
      effort="0"
      velocity="0" />
  </joint>

  <link name="L_thumb_tip_link">
    <visual>
      <origin
        xyz="0 0 0"
        rpy="0 0 0" />
      <geometry>
        <sphere radius="0.005" />
      </geometry>
      <material name="yellow">
        <color rgba="0.9 1 0 1" />
      </material>
    </visual>
  </link>
  <joint name="L_thumb_tip_joint" type="fixed">
    <parent link="L_thumb_distal_link" />
    <child link="L_thumb_tip_link" />
    <origin rpy="0 0 0" xyz="0.035 -0.001 0" />
  </joint>


  <link
    name="L_index_metacarpal_link">
    <inertial>
      <origin
        xyz="-0.00912 0.00394 0"
        rpy="0 0 0" />
      <mass
        value="0.0321" />
      <inertia
        ixx="1.09E-06"
        ixy="1.85E-06"
        ixz="0"
        iyy="7.7E-06"
        iyz="0"
        izz="7.94E-06" />
    </inertial>
    <visual>
      <origin
        xyz="0 0 0"
        rpy="0 0 0" />
      <geometry>
        <mesh
          filename="../meshes/fourier_hand_12dof/L_index_metacarpal_link.STL" />
      </geometry>
      <material
        name="">
        <color
          rgba="1 1 1 1" />
      </material>
    </visual>
    <collision>
      <origin
        xyz="0 0 0"
        rpy="0 0 0" />
      <geometry>
        <mesh
          filename="../meshes/fourier_hand_12dof/L_index_metacarpal_link.STL" />
      </geometry>
    </collision>
  </link>
  <joint
    name="L_index_metacarpal_joint"
    type="revolute">
    <origin
      xyz="0.0305 -0.0118 -0.088496"
      rpy="3.1416 1.4946 0" />
    <parent
      link="L_hand_base_link" />
    <child
      link="L_index_metacarpal_link" />
    <axis
      xyz="0 1 0" />
    <limit
      lower="-0.0524"
      upper="0.2618"
      effort="0"
      velocity="0" />
  </joint>
  <link
    name="L_index_proximal_link">
    <inertial>
      <origin
        xyz="0.01736 0.0045 0"
        rpy="0 0 0" />
      <mass
        value="0.0358" />
      <inertia
        ixx="3.91E-06"
        ixy="-2.7E-7"
        ixz="0"
        iyy="7.43E-06"
        iyz="0"
        izz="7.77E-06" />
    </inertial>
    <visual>
      <origin
        xyz="0 0 0"
        rpy="0 0 0" />
      <geometry>
        <mesh
          filename="../meshes/fourier_hand_12dof/L_index_proximal_link.STL" />
      </geometry>
      <material
        name="">
        <color
          rgba="1 1 1 1" />
      </material>
    </visual>
    <collision>
      <origin
        xyz="0 0 0"
        rpy="0 0 0" />
      <geometry>
        <mesh
          filename="../meshes/fourier_hand_12dof/L_index_proximal_link.STL" />
      </geometry>
    </collision>
  </link>
  <joint
    name="L_index_proximal_joint"
    type="revolute">
    <origin
      xyz="0.012 -0.0005 0"
      rpy="3.1416 0 0" />
    <parent
      link="L_index_metacarpal_link" />
    <child
      link="L_index_proximal_link" />
    <axis
      xyz="0 0 1" />
    <limit
      lower="-1.5185"
      upper="0"
      effort="0"
      velocity="0" />
  </joint>
  <link
    name="L_index_intermediate_link">
    <inertial>
      <origin
        xyz="0.02243 0.002908 1.624e-5"
        rpy="0 0 0" />
      <mass
        value="0.0199" />
      <inertia
        ixx="8.4E-7"
        ixy="4E-8"
        ixz="1E-8"
        iyy="4.82E-6"
        iyz="0"
        izz="4.72E-6" />
    </inertial>
    <visual>
      <origin
        xyz="0 0 0"
        rpy="0 0 0" />
      <geometry>
        <mesh
          filename="../meshes/fourier_hand_12dof/L_index_intermediate_link.STL" />
      </geometry>
      <material
        name="">
        <color
          rgba="1 1 1 1" />
      </material>
    </visual>
    <collision>
      <origin
        xyz="0 0 0"
        rpy="0 0 0" />
      <geometry>
        <mesh
          filename="../meshes/fourier_hand_12dof/L_index_intermediate_link.STL" />
      </geometry>
    </collision>
  </link>
  <joint
    name="L_index_intermediate_joint"
    type="revolute">
    <origin
      xyz="0.038948 0.0020202 0"
      rpy="0 0 -0.19585" />
    <parent
      link="L_index_proximal_link" />
    <child
      link="L_index_intermediate_link" />
    <axis
      xyz="0 0 1" />
    <limit
      lower="-1.5708"
      upper="0"
      effort="0"
      velocity="0" />
  </joint>

  <link name="L_index_tip_link">
    <visual>
      <origin
        xyz="0 0 0"
        rpy="0 0 0" />
      <geometry>
        <sphere radius="0.005" />
      </geometry>
      <material name="yellow">
        <color rgba="0.9 1 0 1" />
      </material>
    </visual>
  </link>
  <joint name="L_index_tip_joint" type="fixed">
    <parent link="L_index_intermediate_link" />
    <child link="L_index_tip_link" />
    <origin rpy="0 0 0" xyz="0.047 0.001 0" />
  </joint>

  <link
    name="L_middle_proximal_link">
    <inertial>
      <origin
        xyz="0.017361 0.0045 0"
        rpy="0 0 0" />
      <mass
        value="0.0358" />
      <inertia
        ixx="3.91E-06"
        ixy="-2.7E-7"
        ixz="0"
        iyy="7.43E-06"
        iyz="0"
        izz="7.77E-06" />
    </inertial>
    <visual>
      <origin
        xyz="0 0 0"
        rpy="0 0 0" />
      <geometry>
        <mesh
          filename="../meshes/fourier_hand_12dof/L_middle_proximal_link.STL" />
      </geometry>
      <material
        name="">
        <color
          rgba="1 1 1 1" />
      </material>
    </visual>
    <collision>
      <origin
        xyz="0 0 0"
        rpy="0 0 0" />
      <geometry>
        <mesh
          filename="../meshes/fourier_hand_12dof/L_middle_proximal_link.STL" />
      </geometry>
    </collision>
  </link>
  <joint
    name="L_middle_proximal_joint"
    type="revolute">
    <origin
      xyz="0.0095 -0.0113 -0.10005"
      rpy="0 1.5708 0" />
    <parent
      link="L_hand_base_link" />
    <child
      link="L_middle_proximal_link" />
    <axis
      xyz="0 0 1" />
    <limit
      lower="-1.5185"
      upper="0"
      effort="0"
      velocity="0" />
  </joint>
  <link
    name="L_middle_intermediate_link">
    <inertial>
      <origin
        xyz="0.0247 0.00323 1.39E-5"
        rpy="0 0 0" />
      <mass
        value="0.0234" />
      <inertia
        ixx="1.01E-6"
        ixy="-4E-8"
        ixz="1E-8"
        iyy="6.94E-6"
        iyz="0"
        izz="6.82E-6" />
    </inertial>
    <visual>
      <origin
        xyz="0 0 0"
        rpy="0 0 0" />
      <geometry>
        <mesh
          filename="../meshes/fourier_hand_12dof/L_middle_intermediate_link.STL" />
      </geometry>
      <material
        name="">
        <color
          rgba="1 1 1 1" />
      </material>
    </visual>
    <collision>
      <origin
        xyz="0 0 0"
        rpy="0 0 0" />
      <geometry>
        <mesh
          filename="../meshes/fourier_hand_12dof/L_middle_intermediate_link.STL" />
      </geometry>
    </collision>
  </link>
  <joint
    name="L_middle_intermediate_joint"
    type="revolute">
    <origin
      xyz="0.038948 0.0020202 0"
      rpy="0 0 -0.19218" />
    <parent
      link="L_middle_proximal_link" />
    <child
      link="L_middle_intermediate_link" />
    <axis
      xyz="0 0 1" />
    <limit
      lower="-1.5708"
      upper="0"
      effort="0"
      velocity="0" />
  </joint>

  <link name="L_middle_tip_link">
    <visual>
      <origin
        xyz="0 0 0"
        rpy="0 0 0" />
      <geometry>
        <sphere radius="0.005" />
      </geometry>
      <material name="yellow">
        <color rgba="0.9 1 0 1" />
      </material>
    </visual>
  </link>
  <joint name="L_middle_tip_joint" type="fixed">
    <parent link="L_middle_intermediate_link" />
    <child link="L_middle_tip_link" />
    <origin rpy="0 0 0" xyz="0.055 0.0012 0" />
  </joint>


  <link
    name="L_ring_proximal_link">
    <inertial>
      <origin
        xyz="0.017361 0.0045 0"
        rpy="0 0 0" />
      <mass
        value="0.035778" />
      <inertia
        ixx="3.91E-06"
        ixy="-2.7E-7"
        ixz="0"
        iyy="7.4E-06"
        iyz="0"
        izz="7.7E-06" />
    </inertial>
    <visual>
      <origin
        xyz="0 0 0"
        rpy="0 0 0" />
      <geometry>
        <mesh
          filename="../meshes/fourier_hand_12dof/L_ring_proximal_link.STL" />
      </geometry>
      <material
        name="">
        <color
          rgba="1 1 1 1" />
      </material>
    </visual>
    <collision>
      <origin
        xyz="0 0 0"
        rpy="0 0 0" />
      <geometry>
        <mesh
          filename="../meshes/fourier_hand_12dof/L_ring_proximal_link.STL" />
      </geometry>
    </collision>
  </link>
  <joint
    name="L_ring_proximal_joint"
    type="revolute">
    <origin
      xyz="-0.010987 -0.0113 -0.10003"
      rpy="-3.1416 1.5184 -3.1416" />
    <parent
      link="L_hand_base_link" />
    <child
      link="L_ring_proximal_link" />
    <axis
      xyz="0 0 1" />
    <limit
      lower="-1.5185"
      upper="0"
      effort="0"
      velocity="0" />
  </joint>
  <link
    name="L_ring_intermediate_link">
    <inertial>
      <origin
        xyz="0.02243 0.002908 1.624E-5"
        rpy="0 0 0" />
      <mass
        value="0.0199" />
      <inertia
        ixx="8.4E-7"
        ixy="4E-8"
        ixz="1E-8"
        iyy="4.82E-6"
        iyz="0"
        izz="4.72E-6" />
    </inertial>
    <visual>
      <origin
        xyz="0 0 0"
        rpy="0 0 0" />
      <geometry>
        <mesh
          filename="../meshes/fourier_hand_12dof/L_ring_intermediate_link.STL" />
      </geometry>
      <material
        name="">
        <color
          rgba="1 1 1 1" />
      </material>
    </visual>
    <collision>
      <origin
        xyz="0 0 0"
        rpy="0 0 0" />
      <geometry>
        <mesh
          filename="../meshes/fourier_hand_12dof/L_ring_intermediate_link.STL" />
      </geometry>
    </collision>
  </link>
  <joint
    name="L_ring_intermediate_joint"
    type="revolute">
    <origin
      xyz="0.038948 0.0020202 0"
      rpy="0 0 -0.19585" />
    <parent
      link="L_ring_proximal_link" />
    <child
      link="L_ring_intermediate_link" />
    <axis
      xyz="0 0 1" />
    <limit
      lower="-1.5708"
      upper="0"
      effort="0"
      velocity="0" />
  </joint>

  <link name="L_ring_tip_link">
    <visual>
      <origin
        xyz="0 0 0"
        rpy="0 0 0" />
      <geometry>
        <sphere radius="0.005" />
      </geometry>
      <material name="green">
        <color rgba="0.9 1 0 1" />
      </material>
    </visual>
  </link>
  <joint name="L_ring_tip_joint" type="fixed">
    <parent link="L_ring_intermediate_link" />
    <child link="L_ring_tip_link" />
    <origin rpy="0 0 0" xyz="0.045 0.001 0" />
  </joint>


  <link
    name="L_pinky_proximal_link">
    <inertial>
      <origin
        xyz="0.017361 0.0045 0"
        rpy="0 0 0" />
      <mass
        value="0.0358" />
      <inertia
        ixx="3.91E-06"
        ixy="-2.7E-7"
        ixz="0"
        iyy="7.4E-06"
        iyz="0"
        izz="7.77E-06" />
    </inertial>
    <visual>
      <origin
        xyz="0 0 0"
        rpy="0 0 0" />
      <geometry>
        <mesh
          filename="../meshes/fourier_hand_12dof/L_pinky_proximal_link.STL" />
      </geometry>
      <material
        name="">
        <color
          rgba="1 1 1 1" />
      </material>
    </visual>
    <collision>
      <origin
        xyz="0 0 0"
        rpy="0 0 0" />
      <geometry>
        <mesh
          filename="../meshes/fourier_hand_12dof/L_pinky_proximal_link.STL" />
      </geometry>
    </collision>
  </link>
  <joint
    name="L_pinky_proximal_joint"
    type="revolute">
    <origin
      xyz="-0.031472 -0.0113 -0.099245"
      rpy="-3.1416 1.4661 -3.1416" />
    <parent
      link="L_hand_base_link" />
    <child
      link="L_pinky_proximal_link" />
    <axis
      xyz="0 0 1" />
    <limit
      lower="-1.5185"
      upper="0"
      effort="0"
      velocity="0" />
  </joint>
  <link
    name="L_pinky_intermediate_link">
    <inertial>
      <origin
        xyz="0.01875 0.00296 5.23E-6"
        rpy="0 0 0" />
      <mass
        value="0.00812" />
      <inertia
        ixx="6.7E-7"
        ixy="5E-8"
        ixz="1E-8"
        iyy="2.69E-06"
        iyz="0"
        izz="2.6E-06" />
    </inertial>
    <visual>
      <origin
        xyz="0 0 0"
        rpy="0 0 0" />
      <geometry>
        <mesh
          filename="../meshes/fourier_hand_12dof/L_pinky_intermediate_link.STL" />
      </geometry>
      <material
        name="">
        <color
          rgba="1 1 1 1" />
      </material>
    </visual>
    <collision>
      <origin
        xyz="0 0 0"
        rpy="0 0 0" />
      <geometry>
        <mesh
          filename="../meshes/fourier_hand_12dof/L_pinky_intermediate_link.STL" />
      </geometry>
    </collision>
  </link>
  <joint
    name="L_pinky_intermediate_joint"
    type="revolute">
    <origin
      xyz="0.038948 0.0020202 0"
      rpy="0 -0.0013299 -0.20067" />
    <parent
      link="L_pinky_proximal_link" />
    <child
      link="L_pinky_intermediate_link" />
    <axis
      xyz="0.0013299 0 1" />
    <limit
      lower="-1.5708"
      upper="0"
      effort="0"
      velocity="0" />
  </joint>

  <link name="L_pinky_tip_link">
    <visual>
      <origin
        xyz="0 0 0"
        rpy="0 0 0" />
      <geometry>
        <sphere radius="0.005" />
      </geometry>
      <material name="yellow">
        <color rgba="0.9 1 0 1" />
      </material>
    </visual>
  </link>
  <joint name="L_pinky_tip_joint" type="fixed">
    <parent link="L_pinky_intermediate_link" />
    <child link="L_pinky_tip_link" />
    <origin rpy="0 0 0" xyz="0.038 0.001 0" />
  </joint>

  <link
    name="right_upper_arm_pitch_link">
    <inertial>
      <origin
        xyz="0.0022312 -0.040265 3.797E-05"
        rpy="0 0 0" />
      <mass
        value="1.3432" />
      <inertia
        ixx="0.0031811"
        ixy="7.306E-05"
        ixz="-1.5E-07"
        iyy="0.0012561"
        iyz="-9E-08"
        izz="0.0030442" />
    </inertial>
    <visual>
      <origin
        xyz="0 0 0"
        rpy="0 0 0" />
      <geometry>
        <mesh
          filename="../meshes/gr2t2v2/right_upper_arm_pitch_link.STL" />
      </geometry>
      <material
        name="">
        <color
          rgba="1 1 1 1" />
      </material>
    </visual>
    <!-- <collision>
      <origin
        xyz="0 0 0"
        rpy="0 0 0" />
      <geometry>
        <mesh
          filename="../meshes/gr2t2v2/right_upper_arm_pitch_link.STL" />
      </geometry>
    </collision> -->
  </link>
  <joint
    name="right_shoulder_pitch_joint"
    type="revolute">
    <origin
      xyz="0 -0.1585 0"
      rpy="0 0 0" />
    <parent
      link="torso_link" />
    <child
      link="right_upper_arm_pitch_link" />
    <axis
      xyz="0 1 0" />
    <limit
      lower="-2.9671"
      upper="2.9671"
      effort="74.45"
      velocity="7.7568" />
  </joint>
  <link
    name="right_upper_arm_roll_link">
    <inertial>
      <origin
        xyz="0.0087432 -0.0022878 -0.038787"
        rpy="0 0 0" />
      <mass
        value="0.96142" />
      <inertia
        ixx="0.0026111"
        ixy="-1.105E-05"
        ixz="-0.00033468"
        iyy="0.0028017"
        iyz="-2.91E-06"
        izz="0.00091191" />
    </inertial>
    <visual>
      <origin
        xyz="0 0 0"
        rpy="0 0 0" />
      <geometry>
        <mesh
          filename="../meshes/gr2t2v2/right_upper_arm_roll_link.STL" />
      </geometry>
      <material
        name="">
        <color
          rgba="1 1 1 1" />
      </material>
    </visual>
    <collision>
      <origin
        xyz="0 0 0"
        rpy="0 0 0" />
      <geometry>
        <sphere radius="0.045"  />
      </geometry>
    </collision>
  </link>
  <joint
    name="right_shoulder_roll_joint"
    type="revolute">
    <origin
      xyz="0 -0.071498 0"
      rpy="0 0 0" />
    <parent
      link="right_upper_arm_pitch_link" />
    <child
      link="right_upper_arm_roll_link" />
    <axis
      xyz="1 0 0" />
    <limit
      lower="-2.7925"
      upper="0.5236"
      effort="74.45"
      velocity="7.7568" />
  </joint>
  <link
    name="right_upper_arm_yaw_link">
    <inertial>
      <origin
        xyz="-0.00056161 -0.0012137 -0.091108"
        rpy="0 0 0" />
      <mass
        value="1.3181" />
      <inertia
        ixx="0.0067903"
        ixy="-3.2E-07"
        ixz="-5.12E-06"
        iyy="0.0068059"
        iyz="-9.238E-05"
        izz="0.0010853" />
    </inertial>
    <visual>
      <origin
        xyz="0 0 0"
        rpy="0 0 0" />
      <geometry>
        <mesh
          filename="../meshes/gr2t2v2/right_upper_arm_yaw_link.STL" />
      </geometry>
      <material
        name="">
        <color
          rgba="1 1 1 1" />
      </material>
    </visual>
    <collision>
      <origin
        xyz="0 0 -0.05"
        rpy="0 0 0" />
      <geometry>
        <cylinder radius="0.040" length="0.1" />
      </geometry>
    </collision>
  </link>
  <joint
    name="right_shoulder_yaw_joint"
    type="revolute">
    <origin
      xyz="0 0 -0.09438"
      rpy="0 0 0" />
    <parent
      link="right_upper_arm_roll_link" />
    <child
      link="right_upper_arm_yaw_link" />
    <axis
      xyz="0 0 1" />
    <limit
      lower="-1.8326"
      upper="1.8326"
      effort="42.75"
      velocity="6.283" />
  </joint>
  <link
    name="right_lower_arm_pitch_link">
    <inertial>
      <origin
        xyz="-0.0014862 -0.006973 -0.021097"
        rpy="0 0 0" />
      <mass
        value="0.45807" />
      <inertia
        ixx="0.00068974"
        ixy="3.65E-06"
        ixz="-2.99E-06"
        iyy="0.00057464"
        iyz="6.575E-05"
        izz="0.00038897" />
    </inertial>
    <visual>
      <origin
        xyz="0 0 0"
        rpy="0 0 0" />
      <geometry>
        <mesh
          filename="../meshes/gr2t2v2/right_lower_arm_pitch_link.STL" />
      </geometry>
      <material
        name="">
        <color
          rgba="1 1 1 1" />
      </material>
    </visual>
    <!-- <collision>
      <origin
        xyz="0 0 0"
        rpy="0 0 0" />
      <geometry>
        <mesh
          filename="../meshes/gr2t2v2/right_lower_arm_pitch_link.STL" />
      </geometry>
    </collision> -->
  </link>
  <joint
    name="right_elbow_pitch_joint"
    type="revolute">
    <origin
      xyz="0 0 -0.16111"
      rpy="0 -0.39265 0" />
    <parent
      link="right_upper_arm_yaw_link" />
    <child
      link="right_lower_arm_pitch_link" />
    <axis
      xyz="0 1 0" />
    <limit
      lower="-1.5272"
      upper="0.47997"
      effort="42.75"
      velocity="6.283" />
  </joint>
  <link
    name="right_hand_yaw_link">
    <inertial>
      <origin
        xyz="0.00027991 -0.0038031 -0.062955"
        rpy="0 0 0" />
      <mass
        value="1.0855" />
      <inertia
        ixx="0.0023598"
        ixy="9.31E-06"
        ixz="2.063E-05"
        iyy="0.002234"
        iyz="-0.00013994"
        izz="0.00088838" />
    </inertial>
    <visual>
      <origin
        xyz="0 0 0"
        rpy="0 0 0" />
      <geometry>
        <mesh
          filename="../meshes/gr2t2v2/right_hand_yaw_link.STL" />
      </geometry>
      <material
        name="">
        <color
          rgba="1 1 1 1" />
      </material>
    </visual>
    <collision>
      <origin
        xyz="0 0 -0.05"
        rpy="0 0 0" />
      <geometry>
        <cylinder radius="0.045" length="0.1155" />
      </geometry>
    </collision>
  </link>
  <joint
    name="right_wrist_yaw_joint"
    type="revolute">
    <origin
      xyz="0 0 -0.058525"
      rpy="0 0 0" />
    <parent
      link="right_lower_arm_pitch_link" />
    <child
      link="right_hand_yaw_link" />
    <axis
      xyz="0 0 1" />
    <limit
      lower="-1.8326"
      upper="1.8326"
      effort="17.325"
      velocity="9.1627" />
  </joint>
  <link
    name="right_hand_pitch_link">
    <inertial>
      <origin
        xyz="0.0038604 -2.7474E-05 2.9411E-06"
        rpy="0 0 0" />
      <mass
        value="0.45716" />
      <inertia
        ixx="0.00021943"
        ixy="3.7E-07"
        ixz="-8.6975E-08"
        iyy="0.00022813"
        iyz="2.1E-07"
        izz="0.00023483" />
    </inertial>
    <visual>
      <origin
        xyz="0 0 0"
        rpy="0 0 0" />
      <geometry>
        <mesh
          filename="../meshes/gr2t2v2/right_hand_pitch_link.STL" />
      </geometry>
      <material
        name="">
        <color
          rgba="1 1 1 1" />
      </material>
    </visual>
    <!-- <collision>
      <origin
        xyz="0 0 0"
        rpy="0 0 0" />
      <geometry>
        <mesh
          filename="../meshes/gr2t2v2/right_hand_pitch_link.STL" />
      </geometry>
    </collision> -->
  </link>
  <joint
    name="right_wrist_pitch_joint"
    type="revolute">
    <origin
      xyz="0 0 -0.16102"
      rpy="0 0 0" />
    <parent
      link="right_hand_yaw_link" />
    <child
      link="right_hand_pitch_link" />
    <axis
      xyz="0 1 0" />
    <limit
      lower="-0.61087"
      upper="0.61087"
      effort="17.325"
      velocity="9.1627" />
  </joint>
  <link
    name="right_hand_roll_link">
    <inertial>
      <origin
        xyz="0.0087325 2.8386E-05 -0.015719"
        rpy="0 0 0" />
      <mass
        value="0.20259" />
      <inertia
        ixx="0.0001134"
        ixy="1.8583E-08"
        ixz="-2.4468E-05"
        iyy="0.00019338"
        iyz="6.0314E-08"
        izz="0.0001471" />
    </inertial>
    <visual>
      <origin
        xyz="0 0 0"
        rpy="0 0 0" />
      <geometry>
        <mesh
          filename="../meshes/gr2t2v2/right_hand_roll_link.STL" />
      </geometry>
      <material
        name="">
        <color
          rgba="1 1 1 1" />
      </material>
    </visual>
    <!-- <collision>
      <origin
        xyz="0 0 0"
        rpy="0 0 0" />
      <geometry>
        <mesh
          filename="../meshes/gr2t2v2/right_hand_roll_link.STL" />
      </geometry>
    </collision> -->
  </link>
  <joint
    name="right_wrist_roll_joint"
    type="revolute">
    <origin
      xyz="0 0 0"
      rpy="0 0 0" />
    <parent
      link="right_hand_pitch_link" />
    <child
      link="right_hand_roll_link" />
    <axis
      xyz="1 0 0" />
    <limit
      lower="-0.95993"
      upper="0.95993"
      effort="17.325"
      velocity="9.1627" />
  </joint>
  <link
    name="right_end_effector_link">
  </link>
  <joint
    name="right_end_effector_joint"
    type="fixed">
    <origin
      xyz="0 0 -0.045"
      rpy="0 0 0" />
    <parent
      link="right_hand_roll_link" />
    <child
      link="right_end_effector_link" />
    <axis
      xyz="0 0 0" />
  </joint>


  <link
    name="R_hand_base_link">
    <inertial>
      <origin
        xyz="-0.0031 0.00970 -0.0440"
        rpy="0 0 0" />
      <mass
        value="0.281" />
      <inertia
        ixx="0.000343"
        ixy="2.91E-06"
        ixz="9.85E-06"
        iyy="0.000474"
        iyz="1.066E-5"
        izz="0.000217" />
    </inertial>
    <visual>
      <origin
        xyz="0 0 0"
        rpy="0 0 0" />
      <geometry>
        <mesh
          filename="../meshes/fourier_hand_12dof/R_hand_base_link.STL" />
      </geometry>
      <material
        name="">
        <color
          rgba="1 1 1 1" />
      </material>
    </visual>
    <collision>
      <origin
        xyz="0 0 0"
        rpy="0 0 0" />
      <geometry>
        <mesh
          filename="../meshes/fourier_hand_12dof/R_hand_base_link.STL" />
      </geometry>
    </collision>
  </link>
  <joint
    name="R_hand_base_joint"
    type="fixed">
    <origin
      xyz="0 0 0"
      rpy="0 0 0" />
    <parent
      link="right_end_effector_link" />
    <child
      link="R_hand_base_link" />
    <axis
      xyz="0 0 0" />
  </joint>
  <link
    name="R_thumb_proximal_yaw_link">
    <inertial>
      <origin
        xyz="0.010856 -0.001425 -0.000443"
        rpy="0 0 0" />
      <mass
        value="0.04" />
      <inertia
        ixx="4.48E-6"
        ixy="7E-7"
        ixz="7.4E-7"
        iyy="7.55E-6"
        iyz="-6E-8"
        izz="6.88E-06" />
    </inertial>
    <visual>
      <origin
        xyz="0 0 0"
        rpy="0 0 0" />
      <geometry>
        <mesh
          filename="../meshes/fourier_hand_12dof/R_thumb_proximal_yaw_link.STL" />
      </geometry>
      <material
        name="">
        <color
          rgba="1 1 1 1" />
      </material>
    </visual>
    <collision>
      <origin
        xyz="0 0 0"
        rpy="0 0 0" />
      <geometry>
        <mesh
          filename="../meshes/fourier_hand_12dof/R_thumb_proximal_yaw_link.STL" />
      </geometry>
    </collision>
  </link>
  <joint
    name="R_thumb_proximal_yaw_joint"
    type="revolute">
    <origin
      xyz="0.014 0.012 -0.023196"
      rpy="3.1416 0 0" />
    <parent
      link="R_hand_base_link" />
    <child
      link="R_thumb_proximal_yaw_link" />
    <axis
      xyz="0 0 1" />
    <limit
      lower="-1.4661"
      upper="0"
      effort="0"
      velocity="0" />
  </joint>
  <link
    name="R_thumb_proximal_pitch_link">
    <inertial>
      <origin
        xyz="0.026421 -0.001244 3.22E-06"
        rpy="0 0 0" />
      <mass
        value="0.0415" />
      <inertia
        ixx="5.78E-06"
        ixy="4.3E-7"
        ixz="0"
        iyy="1.328E-05"
        iyz="0"
        izz="1.39E-05" />
    </inertial>
    <visual>
      <origin
        xyz="0 0 0"
        rpy="0 0 0" />
      <geometry>
        <mesh
          filename="../meshes/fourier_hand_12dof/R_thumb_proximal_pitch_link.STL" />
      </geometry>
      <material
        name="">
        <color
          rgba="1 1 1 1" />
      </material>
    </visual>
    <collision>
      <origin
        xyz="0 0 0"
        rpy="0 0 0" />
      <geometry>
        <mesh
          filename="../meshes/fourier_hand_12dof/R_thumb_proximal_pitch_link.STL" />
      </geometry>
    </collision>
  </link>
  <joint
    name="R_thumb_proximal_pitch_joint"
    type="revolute">
    <origin
      xyz="0.034322 -0.0054361 -0.001"
      rpy="1.5708 0 -0.15708" />
    <parent
      link="R_thumb_proximal_yaw_link" />
    <child
      link="R_thumb_proximal_pitch_link" />
    <axis
      xyz="0 0 1" />
    <limit
      lower="0"
      upper="1.274"
      effort="0"
      velocity="0" />
  </joint>
  <link
    name="R_thumb_distal_link">
    <inertial>
      <origin
        xyz="0.01864 -0.005137 1.57E-05"
        rpy="0 0 0" />
      <mass
        value="0.0198" />
      <inertia
        ixx="1.15E-06"
        ixy="-6E-8"
        ixz="0"
        iyy="3.43E-06"
        iyz="0"
        izz="3.24E-06" />
    </inertial>
    <visual>
      <origin
        xyz="0 0 0"
        rpy="0 0 0" />
      <geometry>
        <mesh
          filename="../meshes/fourier_hand_12dof/R_thumb_distal_link.STL" />
      </geometry>
      <material
        name="">
        <color
          rgba="1 1 1 1" />
      </material>
    </visual>
    <collision>
      <origin
        xyz="0 0 0"
        rpy="0 0 0" />
      <geometry>
        <mesh
          filename="../meshes/fourier_hand_12dof/R_thumb_distal_link.STL" />
      </geometry>
    </collision>
  </link>
  <joint
    name="R_thumb_distal_joint"
    type="revolute">
    <origin
      xyz="0.05175 0.0050976 0"
      rpy="0 0 0.071635" />
    <parent
      link="R_thumb_proximal_pitch_link" />
    <child
      link="R_thumb_distal_link" />
    <axis
      xyz="0 0 1" />
    <limit
      lower="0"
      upper="1.3614"
      effort="0"
      velocity="0" />
  </joint>

  <link name="R_thumb_tip_link">
    <visual>
      <origin
        xyz="0 0 0"
        rpy="0 0 0" />
      <geometry>
        <sphere radius="0.005" />
      </geometry>
      <material name="yellow">
        <color rgba="0.9 1 0 1" />
      </material>
    </visual>
  </link>
  <joint name="R_thumb_tip_joint" type="fixed">
    <parent link="R_thumb_distal_link" />
    <child link="R_thumb_tip_link" />
    <origin rpy="0 0 0" xyz="0.035 -0.001 0" />
  </joint>


  <link
    name="R_index_metacarpal_link">
    <inertial>
      <origin
        xyz="-0.00913 0.003944 0"
        rpy="0 0 0" />
      <mass
        value="0.0321" />
      <inertia
        ixx="1.09E-06"
        ixy="1.85E-06"
        ixz="0"
        iyy="7.7E-06"
        iyz="0"
        izz="7.94E-06" />
    </inertial>
    <visual>
      <origin
        xyz="0 0 0"
        rpy="0 0 0" />
      <geometry>
        <mesh
          filename="../meshes/fourier_hand_12dof/R_index_metacarpal_link.STL" />
      </geometry>
      <material
        name="">
        <color
          rgba="1 1 1 1" />
      </material>
    </visual>
    <collision>
      <origin
        xyz="0 0 0"
        rpy="0 0 0" />
      <geometry>
        <mesh
          filename="../meshes/fourier_hand_12dof/R_index_metacarpal_link.STL" />
      </geometry>
    </collision>
  </link>
  <joint
    name="R_index_metacarpal_joint"
    type="revolute">
    <origin
      xyz="0.0305 0.0118 -0.088496"
      rpy="-3.1416 1.4588 0" />
    <parent
      link="R_hand_base_link" />
    <child
      link="R_index_metacarpal_link" />
    <axis
      xyz="0 1 0" />
    <limit
      lower="-0.0524"
      upper="0.2618"
      effort="0"
      velocity="0" />
  </joint>
  <link
    name="R_index_proximal_link">
    <inertial>
      <origin
        xyz="0.017361 0.0045 0"
        rpy="0 0 0" />
      <mass
        value="0.0358" />
      <inertia
        ixx="3.91E-06"
        ixy="-2.7E-7"
        ixz="0"
        iyy="7.43E-06"
        iyz="0"
        izz="7.77E-06" />
    </inertial>
    <visual>
      <origin
        xyz="0 0 0"
        rpy="0 0 0" />
      <geometry>
        <mesh
          filename="../meshes/fourier_hand_12dof/R_index_proximal_link.STL" />
      </geometry>
      <material
        name="">
        <color
          rgba="1 1 1 1" />
      </material>
    </visual>
    <collision>
      <origin
        xyz="0 0 0"
        rpy="0 0 0" />
      <geometry>
        <mesh
          filename="../meshes/fourier_hand_12dof/R_index_proximal_link.STL" />
      </geometry>
    </collision>
  </link>
  <joint
    name="R_index_proximal_joint"
    type="revolute">
    <origin
      xyz="0.012 0.0005 0"
      rpy="0 0 0" />
    <parent
      link="R_index_metacarpal_link" />
    <child
      link="R_index_proximal_link" />
    <axis
      xyz="0 0 1" />
    <limit
      lower="-1.5185"
      upper="0"
      effort="0"
      velocity="0" />
  </joint>
  <link
    name="R_index_intermediate_link">
    <inertial>
      <origin
        xyz="0.0224 0.002908 1.624E-5"
        rpy="0 0 0" />
      <mass
        value="0.0199" />
      <inertia
        ixx="8.4E-7"
        ixy="4E-8"
        ixz="1E-8"
        iyy="4.82E-6"
        iyz="0"
        izz="4.72E-6" />
    </inertial>
    <visual>
      <origin
        xyz="0 0 0"
        rpy="0 0 0" />
      <geometry>
        <mesh
          filename="../meshes/fourier_hand_12dof/R_index_intermediate_link.STL" />
      </geometry>
      <material
        name="">
        <color
          rgba="1 1 1 1" />
      </material>
    </visual>
    <collision>
      <origin
        xyz="0 0 0"
        rpy="0 0 0" />
      <geometry>
        <mesh
          filename="../meshes/fourier_hand_12dof/R_index_intermediate_link.STL" />
      </geometry>
    </collision>
  </link>
  <joint
    name="R_index_intermediate_joint"
    type="revolute">
    <origin
      xyz="0.038948 0.0020202 0"
      rpy="0 0 -0.19585" />
    <parent
      link="R_index_proximal_link" />
    <child
      link="R_index_intermediate_link" />
    <axis
      xyz="0 0 1" />
    <limit
      lower="-1.5708"
      upper="0"
      effort="0"
      velocity="0" />
  </joint>

  <link name="R_index_tip_link">
    <visual>
      <origin
        xyz="0 0 0"
        rpy="0 0 0" />
      <geometry>
        <sphere radius="0.005" />
      </geometry>
      <material name="yellow">
        <color rgba="0.9 1 0 1" />
      </material>
    </visual>
  </link>
  <joint name="R_index_tip_joint" type="fixed">
    <parent link="R_index_intermediate_link" />
    <child link="R_index_tip_link" />
    <origin rpy="0 0 0" xyz="0.047 0.001 0" />
  </joint>


  <link
    name="R_middle_proximal_link">
    <inertial>
      <origin
        xyz="0.017361 0.0045 0"
        rpy="0 0 0" />
      <mass
        value="0.0358" />
      <inertia
        ixx="3.91E-06"
        ixy="-2.7E-7"
        ixz="0"
        iyy="7.43E-06"
        iyz="0"
        izz="7.77E-06" />
    </inertial>
    <visual>
      <origin
        xyz="0 0 0"
        rpy="0 0 0" />
      <geometry>
        <mesh
          filename="../meshes/fourier_hand_12dof/R_middle_proximal_link.STL" />
      </geometry>
      <material
        name="">
        <color
          rgba="1 1 1 1" />
      </material>
    </visual>
    <collision>
      <origin
        xyz="0 0 0"
        rpy="0 0 0" />
      <geometry>
        <mesh
          filename="../meshes/fourier_hand_12dof/R_middle_proximal_link.STL" />
      </geometry>
    </collision>
  </link>
  <joint
    name="R_middle_proximal_joint"
    type="revolute">
    <origin
      xyz="0.0095 0.0113 -0.10005"
      rpy="3.1416 1.5708 0" />
    <parent
      link="R_hand_base_link" />
    <child
      link="R_middle_proximal_link" />
    <axis
      xyz="0 0 1" />
    <limit
      lower="-1.5185"
      upper="0"
      effort="0"
      velocity="0" />
  </joint>
  <link
    name="R_middle_intermediate_link">
    <inertial>
      <origin
        xyz="0.02470 0.003230 -1.394E-5"
        rpy="0 0 0" />
      <mass
        value="0.0234" />
      <inertia
        ixx="1.01E-6"
        ixy="-4E-8"
        ixz="1E-8"
        iyy="6.94E-6"
        iyz="0"
        izz="6.82E-6" />
    </inertial>
    <visual>
      <origin
        xyz="0 0 0"
        rpy="0 0 0" />
      <geometry>
        <mesh
          filename="../meshes/fourier_hand_12dof/R_middle_intermediate_link.STL" />
      </geometry>
      <material
        name="">
        <color
          rgba="1 1 1 1" />
      </material>
    </visual>
    <collision>
      <origin
        xyz="0 0 0"
        rpy="0 0 0" />
      <geometry>
        <mesh
          filename="../meshes/fourier_hand_12dof/R_middle_intermediate_link.STL" />
      </geometry>
    </collision>
  </link>
  <joint
    name="R_middle_intermediate_joint"
    type="revolute">
    <origin
      xyz="0.038948 0.0020202 0"
      rpy="0 0 -0.19218" />
    <parent
      link="R_middle_proximal_link" />
    <child
      link="R_middle_intermediate_link" />
    <axis
      xyz="0 0 1" />
    <limit
      lower="-1.5708"
      upper="0"
      effort="0"
      velocity="0" />
  </joint>

  <link name="R_middle_tip_link">
    <visual>
      <origin
        xyz="0 0 0"
        rpy="0 0 0" />
      <geometry>
        <sphere radius="0.005" />
      </geometry>
      <material name="yellow">
        <color rgba="0.9 1 0 1" />
      </material>
    </visual>
  </link>
  <joint name="R_middle_tip_joint" type="fixed">
    <parent link="R_middle_intermediate_link" />
    <child link="R_middle_tip_link" />
    <origin rpy="0 0 0" xyz="0.055 0.0012 0" />
  </joint>


  <link
    name="R_ring_proximal_link">
    <inertial>
      <origin
        xyz="0.017361 0.0045 0"
        rpy="0 0 0" />
      <mass
        value="0.035778" />
      <inertia
        ixx="3.91E-06"
        ixy="-2.7E-7"
        ixz="0"
        iyy="7.43E-06"
        iyz="0"
        izz="7.77E-06" />
    </inertial>
    <visual>
      <origin
        xyz="0 0 0"
        rpy="0 0 0" />
      <geometry>
        <mesh
          filename="../meshes/fourier_hand_12dof/R_ring_proximal_link.STL" />
      </geometry>
      <material
        name="">
        <color
          rgba="1 1 1 1" />
      </material>
    </visual>
    <collision>
      <origin
        xyz="0 0 0"
        rpy="0 0 0" />
      <geometry>
        <mesh
          filename="../meshes/fourier_hand_12dof/R_ring_proximal_link.STL" />
      </geometry>
    </collision>
  </link>
  <joint
    name="R_ring_proximal_joint"
    type="revolute">
    <origin
      xyz="-0.010987 0.0113 -0.10003"
      rpy="0 1.5184 3.1416" />
    <parent
      link="R_hand_base_link" />
    <child
      link="R_ring_proximal_link" />
    <axis
      xyz="0 0 1" />
    <limit
      lower="-1.5185"
      upper="0"
      effort="0"
      velocity="0" />
  </joint>
  <link
    name="R_ring_intermediate_link">
    <inertial>
      <origin
        xyz="0.0224 0.002908 1.624E-5"
        rpy="0 0 0" />
      <mass
        value="0.0199" />
      <inertia
        ixx="8.4E-7"
        ixy="4E-8"
        ixz="1E-8"
        iyy="4.82E-6"
        iyz="0"
        izz="4.72E-6" />
    </inertial>
    <visual>
      <origin
        xyz="0 0 0"
        rpy="0 0 0" />
      <geometry>
        <mesh
          filename="../meshes/fourier_hand_12dof/R_ring_intermediate_link.STL" />
      </geometry>
      <material
        name="">
        <color
          rgba="1 1 1 1" />
      </material>
    </visual>
    <collision>
      <origin
        xyz="0 0 0"
        rpy="0 0 0" />
      <geometry>
        <mesh
          filename="../meshes/fourier_hand_12dof/R_ring_intermediate_link.STL" />
      </geometry>
    </collision>
  </link>
  <joint
    name="R_ring_intermediate_joint"
    type="revolute">
    <origin
      xyz="0.038948 0.0020202 0"
      rpy="0 0 -0.19585" />
    <parent
      link="R_ring_proximal_link" />
    <child
      link="R_ring_intermediate_link" />
    <axis
      xyz="0 0 1" />
    <limit
      lower="-1.5708"
      upper="0"
      effort="0"
      velocity="0" />
  </joint>

  <link name="R_ring_tip_link">
    <visual>
      <origin
        xyz="0 0 0"
        rpy="0 0 0" />
      <geometry>
        <sphere radius="0.005" />
      </geometry>
      <material name="green">
        <color rgba="0.9 1 0 1" />
      </material>
    </visual>
  </link>
  <joint name="R_ring_tip_joint" type="fixed">
    <parent link="R_ring_intermediate_link" />
    <child link="R_ring_tip_link" />
    <origin rpy="0 0 0" xyz="0.045 0.001 0" />
  </joint>


  <link
    name="R_pinky_proximal_link">
    <inertial>
      <origin
        xyz="0.017361 0.0045 0"
        rpy="0 0 0" />
      <mass
        value="0.0358" />
      <inertia
        ixx="3.91E-06"
        ixy="-2.7E-7"
        ixz="0"
        iyy="7.43E-06"
        iyz="0"
        izz="7.77E-06" />
    </inertial>
    <visual>
      <origin
        xyz="0 0 0"
        rpy="0 0 0" />
      <geometry>
        <mesh
          filename="../meshes/fourier_hand_12dof/R_pinky_proximal_link.STL" />
      </geometry>
      <material
        name="">
        <color
          rgba="1 1 1 1" />
      </material>
    </visual>
    <collision>
      <origin
        xyz="0 0 0"
        rpy="0 0 0" />
      <geometry>
        <mesh
          filename="../meshes/fourier_hand_12dof/R_pinky_proximal_link.STL" />
      </geometry>
    </collision>
  </link>
  <joint
    name="R_pinky_proximal_joint"
    type="revolute">
    <origin
      xyz="-0.031472 0.0113 -0.099245"
      rpy="0 1.4661 3.1416" />
    <parent
      link="R_hand_base_link" />
    <child
      link="R_pinky_proximal_link" />
    <axis
      xyz="0 0 1" />
    <limit
      lower="-1.5185"
      upper="0"
      effort="0"
      velocity="0" />
  </joint>
  <link
    name="R_pinky_intermediate_link">
    <inertial>
      <origin
        xyz="0.01875 0.00296 5.23E-6"
        rpy="0 0 0" />
      <mass
        value="0.00812" />
      <inertia
        ixx="6.7E-7"
        ixy="5E-8"
        ixz="1E-8"
        iyy="2.69E-06"
        iyz="0"
        izz="2.6E-06" />
    </inertial>
    <visual>
      <origin
        xyz="0 0 0"
        rpy="0 0 0" />
      <geometry>
        <mesh
          filename="../meshes/fourier_hand_12dof/R_pinky_intermediate_link.STL" />
      </geometry>
      <material
        name="">
        <color
          rgba="1 1 1 1" />
      </material>
    </visual>
    <collision>
      <origin
        xyz="0 0 0"
        rpy="0 0 0" />
      <geometry>
        <mesh
          filename="../meshes/fourier_hand_12dof/R_pinky_intermediate_link.STL" />
      </geometry>
    </collision>
  </link>
  <joint
    name="R_pinky_intermediate_joint"
    type="revolute">
    <origin
      xyz="0.038948 0.0020202 0"
      rpy="0 -0.0013299 -0.20067" />
    <parent
      link="R_pinky_proximal_link" />
    <child
      link="R_pinky_intermediate_link" />
    <axis
      xyz="0.0013299 0 1" />
    <limit
      lower="-1.5708"
      upper="0"
      effort="0"
      velocity="0" />
  </joint>

  <link name="R_pinky_tip_link">
    <visual>
      <origin
        xyz="0 0 0"
        rpy="0 0 0" />
      <geometry>
        <sphere radius="0.005" />
      </geometry>
      <material name="yellow">
        <color rgba="0.9 1 0 1" />
      </material>
    </visual>
  </link>
  <joint name="R_pinky_tip_joint" type="fixed">
    <parent link="R_pinky_intermediate_link" />
    <child link="R_pinky_tip_link" />
    <origin rpy="0 0 0" xyz="0.038 0.001 0" />
  </joint>


  <link
    name="left_thigh_pitch_link">
    <inertial>
      <origin
        xyz="-0.035065 0.036467 0.0020083"
        rpy="0 0 0" />
      <mass
        value="2.61" />
      <inertia
        ixx="0.0075932"
        ixy="0.0031974"
        ixz="-8.035E-05"
        iyy="0.0085937"
        iyz="-9.448E-05"
        izz="0.011716" />
    </inertial>
    <visual>
      <origin
        xyz="0 0 0"
        rpy="0 0 0" />
      <geometry>
        <mesh
          filename="../meshes/gr2t2v2/left_thigh_pitch_link.STL" />
      </geometry>
      <material
        name="">
        <color
          rgba="1 1 1 1" />
      </material>
    </visual>
    <!-- <collision>
      <origin
        xyz="0 0 0"
        rpy="0 0 0" />
      <geometry>
        <mesh
          filename="../meshes/gr2t2v2/left_thigh_pitch_link.STL" />
      </geometry>
    </collision> -->
  </link>
  <joint
    name="left_hip_pitch_joint"
    type="revolute">
    <origin
      xyz="0 0.076867 -0.12355"
      rpy="-0.5236 0 0" />
    <parent
      link="base_link" />
    <child
      link="left_thigh_pitch_link" />
    <axis
      xyz="0 1 0" />
    <limit
      lower="-2.618"
      upper="2.618"
      effort="366.05"
      velocity="6.4997" />
  </joint>
  <link
    name="left_thigh_roll_link">
    <inertial>
      <origin
        xyz="0.027776 -0.00010848 -0.0074687"
        rpy="0 0 0" />
      <mass
        value="1.3487" />
      <inertia
        ixx="0.001181"
        ixy="-5.3E-06"
        ixz="0.00034163"
        iyy="0.0026369"
        iyz="-3.01E-06"
        izz="0.0027651" />
    </inertial>
    <visual>
      <origin
        xyz="0 0 0"
        rpy="0 0 0" />
      <geometry>
        <mesh
          filename="../meshes/gr2t2v2/left_thigh_roll_link.STL" />
      </geometry>
      <material
        name="">
        <color
          rgba="1 1 1 1" />
      </material>
    </visual>
    <collision>
      <origin
        xyz="0.025 0 0"
        rpy="0 1.57 0" />
      <geometry>
        <cylinder radius="0.05" length="0.18" />
      </geometry>
    </collision>
  </link>
  <joint
    name="left_hip_roll_joint"
    type="revolute">
    <origin
      xyz="-0.062 0.0729 0"
      rpy="0.5236 0 0" />
    <parent
      link="left_thigh_pitch_link" />
    <child
      link="left_thigh_roll_link" />
    <axis
      xyz="1 0 0" />
    <limit
      lower="-0.59341"
      upper="1.5708"
      effort="95.472"
      velocity="12.362" />
  </joint>
  <link
    name="left_thigh_yaw_link">
    <inertial>
      <origin
        xyz="0.0010147 -0.012758 -0.14387"
        rpy="0 0 0" />
      <mass
        value="5.1152" />
      <inertia
        ixx="0.042296"
        ixy="-8.538E-05"
        ixz="0.00038855"
        iyy="0.043183"
        iyz="0.00098874"
        izz="0.0099198" />
    </inertial>
    <visual>
      <origin
        xyz="0 0 0"
        rpy="0 0 0" />
      <geometry>
        <mesh
          filename="../meshes/gr2t2v2/left_thigh_yaw_link.STL" />
      </geometry>
      <material
        name="">
        <color
          rgba="1 1 1 1" />
      </material>
    </visual>
    <collision>
      <origin
        xyz="0 0 -0.19"
        rpy="0 0 0" />
      <geometry>
        <cylinder radius="0.06" length="0.26" />
      </geometry>
    </collision>
  </link>
  <joint
    name="left_hip_yaw_joint"
    type="revolute">
    <origin
      xyz="0.062 0 -0.03495"
      rpy="0 0 0" />
    <parent
      link="left_thigh_roll_link" />
    <child
      link="left_thigh_yaw_link" />
    <axis
      xyz="0 0 1" />
    <limit
      lower="-0.69813"
      upper="1.5708"
      effort="54.33"
      velocity="14.745" />
  </joint>
  <link
    name="left_shank_pitch_link">
    <inertial>
      <origin
        xyz="0.004743 -0.0014414 -0.1756"
        rpy="0 0 0" />
      <mass
        value="3.5932" />
      <inertia
        ixx="0.034881"
        ixy="-1.912E-05"
        ixz="-6.005E-05"
        iyy="0.035366"
        iyz="0.0010678"
        izz="0.0043262" />
    </inertial>
    <visual>
      <origin
        xyz="0 0 0"
        rpy="0 0 0" />
      <geometry>
        <mesh
          filename="../meshes/gr2t2v2/left_shank_pitch_link.STL" />
      </geometry>
      <material
        name="">
        <color
          rgba="1 1 1 1" />
      </material>
    </visual>
    <collision>
      <origin
        xyz="0 0 -0.165"
        rpy="0 0 0" />
      <geometry>
        <cylinder radius="0.05" length="0.18" />
      </geometry>
    </collision>
  </link>
  <joint
    name="left_knee_pitch_joint"
    type="revolute">
    <origin
      xyz="0 0 -0.34305"
      rpy="0 0 0" />
    <parent
      link="left_thigh_yaw_link" />
    <child
      link="left_shank_pitch_link" />
    <axis
      xyz="0 1 0" />
    <limit
      lower="-0.087266"
      upper="2.3562"
      effort="366.05"
      velocity="6.4997" />
  </joint>
  <link
    name="left_foot_pitch_link">
    <inertial>
      <origin
        xyz="0.026267 1.226E-05 0.0010987"
        rpy="0 0 0" />
      <mass
        value="0.17877" />
      <inertia
        ixx="1.261E-05"
        ixy="-9E-08"
        ixz="5.14E-06"
        iyy="0.00021914"
        iyz="-1.8E-07"
        izz="0.00022011" />
    </inertial>
    <visual>
      <origin
        xyz="0 0 0"
        rpy="0 0 0" />
      <geometry>
        <mesh
          filename="../meshes/gr2t2v2/left_foot_pitch_link.STL" />
      </geometry>
      <material
        name="">
        <color
          rgba="1 1 1 1" />
      </material>
    </visual>
    <!-- <collision>
      <origin
        xyz="0 0 0"
        rpy="0 0 0" />
      <geometry>
        <mesh
          filename="../meshes/gr2t2v2/left_foot_pitch_link.STL" />
      </geometry>
    </collision> -->
  </link>
  <joint
    name="left_ankle_pitch_joint"
    type="revolute">
    <origin
      xyz="0 0 -0.406"
      rpy="0 0 0" />
    <parent
      link="left_shank_pitch_link" />
    <child
      link="left_foot_pitch_link" />
    <axis
      xyz="0 1 0" />
    <limit
      lower="-0.7854"
      upper="0.7854"
      effort="54.33"
      velocity="14.745" />
  </joint>
  <link
    name="left_foot_roll_link">
    <inertial>
      <origin
        xyz="0.050086 0.006159 -0.032795"
        rpy="0 0 0" />
      <mass
        value="1.1232" />
      <inertia
        ixx="0.0012612"
        ixy="0.00033767"
        ixz="0.00043059"
        iyy="0.0067074"
        iyz="-0.00019341"
        izz="0.0072126" />
    </inertial>
    <visual>
      <origin
        xyz="0 0 0"
        rpy="0 0 0" />
      <geometry>
        <mesh
          filename="../meshes/gr2t2v2/left_foot_roll_link.STL" />
      </geometry>
      <material
        name="">
        <color
          rgba="1 1 1 1" />
      </material>
    </visual>
    <!-- <collision>
      <origin
        xyz="0.06 0 -0.048"
        rpy="0 0 0" />
      <geometry>
        <box size='0.28 0.1 0.02' />
      </geometry>
    </collision> -->


    <collision>
      <origin
        xyz="0.06 -0.025 -0.033"
        rpy="0 1.57 0" />
      <geometry>
        <cylinder radius='0.025' length='0.28' />
      </geometry>
    </collision>
    <collision>
      <origin
        xyz="0.06 0.025 -0.033"
        rpy="0 1.57 0" />
      <geometry>
        <cylinder radius='0.025' length='0.28' />
      </geometry>
    </collision>
  </link>
  <joint
    name="left_ankle_roll_joint"
    type="revolute">
    <origin
      xyz="0 0 0"
      rpy="0 0 0" />
    <parent
      link="left_foot_pitch_link" />
    <child
      link="left_foot_roll_link" />
    <axis
      xyz="1 0 0" />
    <limit
      lower="-0.38397"
      upper="0.38397"
      effort="29.835"
      velocity="16.755" />
  </joint>
  <link
    name="right_thigh_pitch_link">
    <inertial>
      <origin
        xyz="-0.035065 -0.036467 0.0020083"
        rpy="0 0 0" />
      <mass
        value="2.61" />
      <inertia
        ixx="0.0075932"
        ixy="-0.0031974"
        ixz="-8.035E-05"
        iyy="0.0085937"
        iyz="9.448E-05"
        izz="0.011716" />
    </inertial>
    <visual>
      <origin
        xyz="0 0 0"
        rpy="0 0 0" />
      <geometry>
        <mesh
          filename="../meshes/gr2t2v2/right_thigh_pitch_link.STL" />
      </geometry>
      <material
        name="">
        <color
          rgba="1 1 1 1" />
      </material>
    </visual>
    <!-- <collision>
      <origin
        xyz="0 0 0"
        rpy="0 0 0" />
      <geometry>
        <mesh
          filename="../meshes/gr2t2v2/right_thigh_pitch_link.STL" />
      </geometry>
    </collision> -->
  </link>
  <joint
    name="right_hip_pitch_joint"
    type="revolute">
    <origin
      xyz="0 -0.076867 -0.12355"
      rpy="0.5236 0 0" />
    <parent
      link="base_link" />
    <child
      link="right_thigh_pitch_link" />
    <axis
      xyz="0 1 0" />
    <limit
      lower="-2.618"
      upper="2.618"
      effort="366.05"
      velocity="6.4997" />
  </joint>
  <link
    name="right_thigh_roll_link">
    <inertial>
      <origin
        xyz="0.027776 0.00010848 -0.0074687"
        rpy="0 0 0" />
      <mass
        value="1.3487" />
      <inertia
        ixx="0.001181"
        ixy="5.3E-06"
        ixz="0.00034163"
        iyy="0.0026369"
        iyz="3.01E-06"
        izz="0.0027651" />
    </inertial>
    <visual>
      <origin
        xyz="0 0 0"
        rpy="0 0 0" />
      <geometry>
        <mesh
          filename="../meshes/gr2t2v2/right_thigh_roll_link.STL" />
      </geometry>
      <material
        name="">
        <color
          rgba="1 1 1 1" />
      </material>
    </visual>
    <collision>
      <origin
        xyz="0.025 0 0"
        rpy="0 1.57 0" />
      <geometry>
        <cylinder radius="0.05" length="0.18" />
      </geometry>
    </collision>
  </link>
  <joint
    name="right_hip_roll_joint"
    type="revolute">
    <origin
      xyz="-0.062 -0.0729 0"
      rpy="-0.5236 0 0" />
    <parent
      link="right_thigh_pitch_link" />
    <child
      link="right_thigh_roll_link" />
    <axis
      xyz="1 0 0" />
    <limit
      lower="-1.5708"
      upper="0.59341"
      effort="95.472"
      velocity="12.362" />
  </joint>
  <link
    name="right_thigh_yaw_link">
    <inertial>
      <origin
        xyz="0.0010147 0.012758 -0.14387"
        rpy="0 0 0" />
      <mass
        value="5.1152" />
      <inertia
        ixx="0.042296"
        ixy="8.538E-05"
        ixz="0.00038855"
        iyy="0.043183"
        iyz="-0.00098874"
        izz="0.0099198" />
    </inertial>
    <visual>
      <origin
        xyz="0 0 0"
        rpy="0 0 0" />
      <geometry>
        <mesh
          filename="../meshes/gr2t2v2/right_thigh_yaw_link.STL" />
      </geometry>
      <material
        name="">
        <color
          rgba="1 1 1 1" />
      </material>
    </visual>
    <collision>
      <origin
        xyz="0 0 -0.19"
        rpy="0 0 0" />
      <geometry>
        <cylinder radius="0.06" length="0.26" />
      </geometry>
    </collision>
  </link>
  <joint
    name="right_hip_yaw_joint"
    type="revolute">
    <origin
      xyz="0.062 0 -0.03495"
      rpy="0 0 0" />
    <parent
      link="right_thigh_roll_link" />
    <child
      link="right_thigh_yaw_link" />
    <axis
      xyz="0 0 1" />
    <limit
      lower="-1.5708"
      upper="0.69813"
      effort="54.33"
      velocity="14.745" />
  </joint>
  <link
    name="right_shank_pitch_link">
    <inertial>
      <origin
        xyz="0.004743 0.0014414 -0.1756"
        rpy="0 0 0" />
      <mass
        value="3.5932" />
      <inertia
        ixx="0.034881"
        ixy="1.912E-05"
        ixz="-6.005E-05"
        iyy="0.035366"
        iyz="-0.0010678"
        izz="0.0043262" />
    </inertial>
    <visual>
      <origin
        xyz="0 0 0"
        rpy="0 0 0" />
      <geometry>
        <mesh
          filename="../meshes/gr2t2v2/right_shank_pitch_link.STL" />
      </geometry>
      <material
        name="">
        <color
          rgba="1 1 1 1" />
      </material>
    </visual>
    <collision>
      <origin
        xyz="0 0 -0.165"
        rpy="0 0 0" />
      <geometry>
        <cylinder radius="0.05" length="0.18" />
      </geometry>
    </collision>
  </link>
  <joint
    name="right_knee_pitch_joint"
    type="revolute">
    <origin
      xyz="0 0 -0.34305"
      rpy="0 0 0" />
    <parent
      link="right_thigh_yaw_link" />
    <child
      link="right_shank_pitch_link" />
    <axis
      xyz="0 1 0" />
    <limit
      lower="-0.087266"
      upper="2.3562"
      effort="366.05"
      velocity="6.4997" />
  </joint>
  <link
    name="right_foot_pitch_link">
    <inertial>
      <origin
        xyz="0.026267 -1.226E-05 0.0010987"
        rpy="0 0 0" />
      <mass
        value="0.17877" />
      <inertia
        ixx="1.261E-05"
        ixy="9E-08"
        ixz="5.14E-06"
        iyy="0.00021914"
        iyz="1.8E-07"
        izz="0.00022011" />
    </inertial>
    <visual>
      <origin
        xyz="0 0 0"
        rpy="0 0 0" />
      <geometry>
        <mesh
          filename="../meshes/gr2t2v2/right_foot_pitch_link.STL" />
      </geometry>
      <material
        name="">
        <color
          rgba="1 1 1 1" />
      </material>
    </visual>
    <!-- <collision>
      <origin
        xyz="0 0 0"
        rpy="0 0 0" />
      <geometry>
        <mesh
          filename="../meshes/gr2t2v2/right_foot_pitch_link.STL" />
      </geometry>
    </collision> -->
  </link>
  <joint
    name="right_ankle_pitch_joint"
    type="revolute">
    <origin
      xyz="0 0 -0.406"
      rpy="0 0 0" />
    <parent
      link="right_shank_pitch_link" />
    <child
      link="right_foot_pitch_link" />
    <axis
      xyz="0 1 0" />
    <limit
      lower="-0.7854"
      upper="0.7854"
      effort="54.33"
      velocity="14.745" />
  </joint>
  <link
    name="right_foot_roll_link">
    <inertial>
      <origin
        xyz="0.050086 -0.006159 -0.032795"
        rpy="0 0 0" />
      <mass
        value="1.1232" />
      <inertia
        ixx="0.0012612"
        ixy="-0.00033767"
        ixz="0.00043059"
        iyy="0.0067074"
        iyz="0.00019341"
        izz="0.0072126" />
    </inertial>
    <visual>
      <origin
        xyz="0 0 0"
        rpy="0 0 0" />
      <geometry>
        <mesh
          filename="../meshes/gr2t2v2/right_foot_roll_link.STL" />
      </geometry>
      <material
        name="">
        <color
          rgba="1 1 1 1" />
      </material>
    </visual>
    <!-- <collision>
      <origin
        xyz="0.06 0 -0.048"
        rpy="0 0 0" />
      <geometry>
        <box size='0.28 0.1 0.02' />
      </geometry>
    </collision> -->

    <collision>
      <origin
        xyz="0.06 -0.025 -0.033"
        rpy="0 1.57 0" />
      <geometry>
        <cylinder radius='0.025' length='0.28' />
      </geometry>
    </collision>
    <collision>
      <origin
        xyz="0.06 0.025 -0.033"
        rpy="0 1.57 0" />
      <geometry>
        <cylinder radius='0.025' length='0.28' />
      </geometry>
    </collision>
  </link>
  <joint
    name="right_ankle_roll_joint"
    type="revolute">
    <origin
      xyz="0 0 0"
      rpy="0 0 0" />
    <parent
      link="right_foot_pitch_link" />
    <child
      link="right_foot_roll_link" />
    <axis
      xyz="1 0 0" />
    <limit
      lower="-0.38397"
      upper="0.38397"
      effort="29.835"
      velocity="16.755" />
  </joint>
  <link
    name="imu_link">
    <inertial>
      <origin
        xyz="0 0 0"
        rpy="0 0 0" />
      <mass
        value="0" />
      <inertia
        ixx="0"
        ixy="0"
        ixz="0"
        iyy="0"
        iyz="0"
        izz="0" />
    </inertial>

  </link>
  <joint
    name="imu_joint"
    type="fixed">
    <origin
      xyz="-0.059 0 -0.068"
      rpy="0 0 0" />
    <parent
      link="base_link" />
    <child
      link="imu_link" />
    <axis
      xyz="0 0 0" />
  </joint>
</robot>